Workbook

Sheet Trials 1 Outcome - n=100 - OG
B1: =COUNT(B3:B1048576) -> 98 | C1: =AVERAGE(C2:C100) -> 1058.3141 | G1: =COUNT(G3:G1048576) -> 107 | H1: =AVERAGE(H2:H1048576) -> 1096.9726 | L1: =COUNT(L3:L1048576) -> 101 | M1: =AVERAGE(M2:M1048576) -> 1027.8738 | Q1: =COUNT(Q3:Q1048576) -> 104 | R1: =AVERAGE(R2:R1048576) -> 1095.0692 | V1: =COUNT(V3:V1048576) -> 106 | W1: =AVERAGE(W2:W1048576) -> 1073.6072 | AA1: =COUNT(AA3:AA1048576) -> 105 | AB1: =AVERAGE(AB2:AB1048576) -> 1096.8258 | AF1: =COUNT(AF3:AF1048576) -> 101 | AG1: =AVERAGE(AG2:AG1048576) -> 1109.144 | AK1: =COUNT(AK3:AK1048576) -> 101 | AL1: =AVERAGE(AL2:AL1048576) -> 983.31874 | AP1: =COUNT(AP3:AP1048576) -> 92 | AQ1: =AVERAGE(AQ2:AQ1048576) -> 988.94066 | AU1: =COUNT(AU3:AU1048576) -> 100 | AV1: =AVERAGE(AV2:AV1048576) -> 1085.4239 | AZ1: =COUNT(AZ3:AZ1048576) -> 98 | BA1: =AVERAGE(BA2:BA1048576) -> 1041.9836 | BE1: =COUNT(BE3:BE1048576) -> 96 | BF1: =AVERAGE(BF2:BF1048576) -> 1043.1235 | BJ1: =COUNT(BJ3:BJ1048576) -> 93 | BK1: =AVERAGE(BK2:BK1048576) -> 984.84144 | BO1: =COUNT(BO3:BO1048576) -> 97 | BP1: =AVERAGE(BP2:BP1048576) -> 1014.7851 | BT1: =COUNT(BT3:BT1048576) -> 97 | BU1: =AVERAGE(BU2:BU1048576) -> 1058.2111 | BY1: =COUNT(BY3:BY1048576) -> 103 | BZ1: =AVERAGE(BZ2:BZ1048576) -> 1100.4003 | CD1: =COUNT(CD3:CD1048576) -> 104 | CE1: =AVERAGE(CE2:CE1048576) -> 1119.2578 | CI1: =COUNT(CI3:CI1048576) -> 96 | CJ1: =AVERAGE(CJ2:CJ1048576) -> 937.47468 | CN1: =COUNT(CN3:CN1048576) -> 99 | CO1: =AVERAGE(CO2:CO1048576) -> 1067.0385 | CS1: =COUNT(CS3:CS1048576) -> 99 | CT1: =AVERAGE(CT2:CT1048576) -> 992.208 | CX1: =COUNT(CX3:CX1048576) -> 101 | CY1: =AVERAGE(CY2:CY1048576) -> 1040.8769 | DC1: =COUNT(DC3:DC1048576) -> 100 | DD1: =AVERAGE(DD2:DD1048576) -> 1050.698 | DH1: =COUNT(DH3:DH1048576) -> 100 | DI1: =AVERAGE(DI2:DI1048576) -> 1060.6579 | DM1: =COUNT(DM3:DM1048576) -> 103 | DN1: =AVERAGE(DN2:DN1048576) -> 1101.6598 | DR1: =COUNT(DR3:DR1048576) -> 94 | DS1: =AVERAGE(DS2:DS1048576) -> 1037.8151 | DW1: =COUNT(DW3:DW1048576) -> 103 | DX1: =AVERAGE(DX2:DX1048576) -> 1096.8905 | EB1: =COUNT(EB3:EB1048576) -> 99 | EC1: =AVERAGE(EC2:EC1048576) -> 1044.9888 | EG1: =COUNT(EG3:EG1048576) -> 94 | EH1: =AVERAGE(EH2:EH1048576) -> 991.02399 | EL1: =COUNT(EL3:EL1048576) -> 101 | EM1: =AVERAGE(EM2:EM1048576) -> 1058.1382 | EQ1: =COUNT(EQ3:EQ1048576) -> 100 | ER1: =AVERAGE(ER2:ER1048576) -> 967.90144 | EV1: =COUNT(EV3:EV1048576) -> 107 | EW1: =AVERAGE(EW2:EW1048576) -> 1082.5886 | FA1: =COUNT(FA3:FA1048576) -> 95 | FB1: =AVERAGE(FB2:FB1048576) -> 1007.1961 | FF1: =COUNT(FF3:FF1048576) -> 104 | FG1: =AVERAGE(FG2:FG1048576) -> 1053.2727 | FK1: =COUNT(FK3:FK1048576) -> 101 | FL1: =AVERAGE(FL2:FL1048576) -> 1068.4903 | FP1: =COUNT(FP3:FP1048576) -> 97 | FQ1: =AVERAGE(FQ2:FQ1048576) -> 1008.9349 | FU1: =COUNT(FU3:FU1048576) -> 96 | FV1: =AVERAGE(FV2:FV1048576) -> 1000.597 | FZ1: =COUNT(FZ3:FZ1048576) -> 100 | GA1: =AVERAGE(GA2:GA1048576) -> 1090.7329 | GE1: =COUNT(GE3:GE1048576) -> 99 | GF1: =AVERAGE(GF2:GF1048576) -> 1010.5766 | GJ1: =COUNT(GJ3:GJ1048576) -> 99 | GK1: =AVERAGE(GK2:GK1048576) -> 1031.0226 | GO1: =COUNT(GO3:GO1048576) -> 102 | GP1: =AVERAGE(GP2:GP1048576) -> 1088.4227 | GT1: =COUNT(GT3:GT1048576) -> 95 | GU1: =AVERAGE(GU2:GU1048576) -> 976.62432 | GY1: =COUNT(GY3:GY1048576) -> 106 | GZ1: =AVERAGE(GZ2:GZ1048576) -> 1103.6397 | HD1: =COUNT(HD3:HD1048576) -> 105 | HE1: =AVERAGE(HE2:HE1048576) -> 1108.8107 | HI1: =COUNT(HI3:HI1048576) -> 103 | HJ1: =AVERAGE(HJ2:HJ1048576) -> 1111.8894 | HN1: =COUNT(HN3:HN1048576) -> 100 | HO1: =AVERAGE(HO2:HO1048576) -> 1045.5715 | HS1: =COUNT(HS3:HS1048576) -> 98 | HT1: =AVERAGE(HT2:HT1048576) -> 1026.3228 | HX1: =COUNT(HX3:HX1048576) -> 100 | HY1: =AVERAGE(HY2:HY1048576) -> 1028.9002 | IC1: =COUNT(IC3:IC1048576) -> 102 | ID1: =AVERAGE(ID2:ID1048576) -> 1056.8775 | IH1: =COUNT(IH3:IH1048576) -> 99 | II1: =AVERAGE(II2:II1048576) -> 1011.483 | IM1: =COUNT(IM3:IM1048576) -> 95 | IN1: =AVERAGE(IN2:IN1048576) -> 979.06732 | IR1: =COUNT(IR3:IR1048576) -> 99 | IS1: =AVERAGE(IS2:IS1048576) -> 1050.8609 | IW1: =COUNT(IW3:IW1048576) -> 101 | IX1: =AVERAGE(IX2:IX1048576) -> 1074.3955 | JB1: =COUNT(JB3:JB1048576) -> 105 | JC1: =AVERAGE(JC2:JC1048576) -> 1079.6614 | JG1: =COUNT(JG3:JG1048576) -> 99 | JH1: =AVERAGE(JH2:JH1048576) -> 1004.5471 | JL1: =COUNT(JL3:JL1048576) -> 98 | JM1: =AVERAGE(JM2:JM1048576) -> 1062.3833 | JQ1: =COUNT(JQ3:JQ1048576) -> 97 | JR1: =AVERAGE(JR2:JR1048576) -> 1004.1093 | JV1: =COUNT(JV3:JV1048576) -> 95 | JW1: =AVERAGE(JW2:JW1048576) -> 986.22554 | KA1: =COUNT(KA3:KA1048576) -> 102 | KB1: =AVERAGE(KB2:KB1048576) -> 1059.5648 | KF1: =COUNT(KF3:KF1048576) -> 99 | KG1: =AVERAGE(KG2:KG1048576) -> 1063.8048 | KK1: =COUNT(KK3:KK1048576) -> 103 | KL1: =AVERAGE(KL2:KL1048576) -> 1032.6759 | KP1: =COUNT(KP3:KP1048576) -> 109 | KQ1: =AVERAGE(KQ2:KQ1048576) -> 1069.5565 | KR1: =_xlfn.VAR.P(KP2:KP1048576) -> 1.5498695 | KU1: =COUNT(KU3:KU1048576) -> 101 | KV1: =AVERAGE(KV2:KV1048576) -> 1102.7124 | KW1: =_xlfn.VAR.P(KU2:KU1048576) -> 0.73463386 | KZ1: =COUNT(KZ3:KZ1048576) -> 104 | LA1: =AVERAGE(LA2:LA1048576) -> 1073.3642 | LB1: =_xlfn.VAR.P(KZ2:KZ1048576) -> 0.80140533 | LE1: =COUNT(LE3:LE1048576) -> 104 | LF1: =AVERAGE(LF2:LF1048576) -> 1069.5924 | LG1: =_xlfn.VAR.P(LE2:LE1048576) -> 0.9408284 | LJ1: =COUNT(LJ3:LJ1048576) -> 100 | LK1: =AVERAGE(LK2:LK1048576) -> 1050.8843 | LL1: =_xlfn.VAR.P(LJ2:LJ1048576) -> 0.9816 | LO1: =COUNT(LO3:LO1048576) -> 106 | LP1: =AVERAGE(LP2:LP1048576) -> 1103.483 | LQ1: =_xlfn.VAR.P(LO2:LO1048576) -> 1.2050552 | LT1: =COUNT(LT3:LT1048576) -> 102 | LU1: =AVERAGE(LU2:LU1048576) -> 1053.6616 | LV1: =_xlfn.VAR.P(LT2:LT1048576) -> 1.0457516 | LY1: =COUNT(LY3:LY1048576) -> 102 | LZ1: =AVERAGE(LZ2:LZ1048576) -> 1088.8074 | MA1: =_xlfn.VAR.P(LY2:LY1048576) -> 0.83352557 | MD1: =COUNT(MD3:MD1048576) -> 98 | ME1: =AVERAGE(ME2:ME1048576) -> 1044.5024 | MF1: =_xlfn.VAR.P(MD2:MD1048576) -> 1.089546 | MI1: =COUNT(MI3:MI1048576) -> 94 | MJ1: =AVERAGE(MJ2:MJ1048576) -> 1013.0301 | MK1: =_xlfn.VAR.P(MI2:MI1048576) -> 1.0991399 | MN1: =COUNT(MN3:MN1048576) -> 102 | MO1: =AVERAGE(MO2:MO1048576) -> 1071.8904 | MP1: =_xlfn.VAR.P(MN2:MN1048576) -> 0.68589004 | MS1: =COUNT(MS3:MS1048576) -> 101 | MT1: =AVERAGE(MT2:MT1048576) -> 1082.7935 | MU1: =_xlfn.VAR.P(MS2:MS1048576) -> 1.1575336 | MX1: =COUNT(MX3:MX1048576) -> 97 | MY1: =AVERAGE(MY2:MY1048576) -> 1005.1871 | MZ1: =_xlfn.VAR.P(MX2:MX1048576) -> 1.0105218 | NC1: =COUNT(NC3:NC1048576) -> 106 | ND1: =AVERAGE(ND2:ND1048576) -> 1171.154 | NE1: =_xlfn.VAR.P(NC2:NC1048576) -> 1.2132431 | NH1: =COUNT(NH3:NH1048576) -> 97 | NI1: =AVERAGE(NI2:NI1048576) -> 992.49519 | NJ1: =_xlfn.VAR.P(NH2:NH1048576) -> 0.90806674 | NM1: =COUNT(NM3:NM1048576) -> 104 | NN1: =AVERAGE(NN2:NN1048576) -> 1113.9603 | NO1: =_xlfn.VAR.P(NM2:NM1048576) -> 0.9966716 | NR1: =COUNT(NR3:NR1048576) -> 93 | NS1: =AVERAGE(NS2:NS1048576) -> 984.68792 | NT1: =_xlfn.VAR.P(NR2:NR1048576) -> 1.2933287 | NW1: =COUNT(NW3:NW1048576) -> 103 | NX1: =AVERAGE(NX2:NX1048576) -> 1067.6598 | NY1: =_xlfn.VAR.P(NW2:NW1048576) -> 0.88038458 | OB1: =COUNT(OB3:OB1048576) -> 104 | OC1: =AVERAGE(OC2:OC1048576) -> 1072.0837 | OD1: =_xlfn.VAR.P(OB2:OB1048576) -> 1.1061391 | OG1: =COUNT(OG3:OG1048576) -> 90 | OH1: =AVERAGE(OH2:OH1048576) -> 999.41124 | OI1: =_xlfn.VAR.P(OG2:OG1048576) -> 1.1802469 | OL1: =COUNT(OL3:OL1048576) -> 102 | OM1: =AVERAGE(OM2:OM1048576) -> 1063.7084 | ON1: =_xlfn.VAR.P(OL2:OL1048576) -> 1.0146098 | OQ1: =COUNT(OQ3:OQ1048576) -> 101 | OR1: =AVERAGE(OR2:OR1048576) -> 1042.1159 | OS1: =_xlfn.VAR.P(OQ2:OQ1048576) -> 0.86618959 | OV1: =COUNT(OV3:OV1048576) -> 103 | OW1: =AVERAGE(OW2:OW1048576) -> 1108.6658 | OX1: =_xlfn.VAR.P(OV2:OV1048576) -> 0.88962202 | PA1: =COUNT(PA3:PA1048576) -> 100 | PB1: =AVERAGE(PB2:PB1048576) -> 1106.0484 | PC1: =_xlfn.VAR.P(PA2:PA1048576) -> 0.8536 | PF1: =COUNT(PF3:PF1048576) -> 108 | PG1: =AVERAGE(PG2:PG1048576) -> 1103.5939 | PH1: =_xlfn.VAR.P(PF2:PF1048576) -> 1.1920439 | PK1: =COUNT(PK3:PK1048576) -> 95 | PL1: =AVERAGE(PL2:PL1048576) -> 982.22672 | PM1: =_xlfn.VAR.P(PK2:PK1048576) -> 0.71734072 | PP1: =COUNT(PP3:PP1048576) -> 100 | PQ1: =AVERAGE(PQ2:PQ1048576) -> 1024.4269 | PR1: =_xlfn.VAR.P(PP2:PP1048576) -> 1.1404 | PU1: =COUNT(PU3:PU1048576) -> 99 | PV1: =AVERAGE(PV2:PV1048576) -> 1034.183 | PW1: =_xlfn.VAR.P(PU2:PU1048576) -> 1.3672074 | PZ1: =COUNT(PZ3:PZ1048576) -> 100 | QA1: =AVERAGE(QA2:QA1048576) -> 1059.197 | QB1: =_xlfn.VAR.P(PZ2:PZ1048576) -> 1.2516 | QE1: =COUNT(QE3:QE1048576) -> 102 | QF1: =AVERAGE(QF2:QF1048576) -> 1108.0825 | QG1: =_xlfn.VAR.P(QE2:QE1048576) -> 1.1103422 | QJ1: =COUNT(QJ3:QJ1048576) -> 101 | QK1: =AVERAGE(QK2:QK1048576) -> 1061.0778 | QL1: =_xlfn.VAR.P(QJ2:QJ1048576) -> 0.91990981 | QO1: =COUNT(QO3:QO1048576) -> 106 | QP1: =AVERAGE(QP2:QP1048576) -> 1124.5657 | QQ1: =_xlfn.VAR.P(QO2:QO1048576) -> 0.92915628 | QT1: =COUNT(QT3:QT1048576) -> 93 | QU1: =AVERAGE(QU2:QU1048576) -> 1017.1436 | QV1: =_xlfn.VAR.P(QT2:QT1048576) -> 1.439704 | QY1: =COUNT(QY3:QY1048576) -> 95 | QZ1: =AVERAGE(QZ2:QZ1048576) -> 1004.2198 | RA1: =_xlfn.VAR.P(QY2:QY1048576) -> 0.80110803 | RD1: =COUNT(RD3:RD1048576) -> 99 | RE1: =AVERAGE(RE2:RE1048576) -> 1081.0822 | RF1: =_xlfn.VAR.P(RD2:RD1048576) -> 1.0513213 | RI1: =COUNT(RI3:RI1048576) -> 104 | RJ1: =AVERAGE(RJ2:RJ1048576) -> 1112.9863 | RK1: =_xlfn.VAR.P(RI2:RI1048576) -> 0.93306213 | RN1: =COUNT(RN3:RN1048576) -> 107 | RO1: =AVERAGE(RO2:RO1048576) -> 1115.768 | RP1: =_xlfn.VAR.P(RN2:RN1048576) -> 0.82120709 | RS1: =COUNT(RS3:RS1048576) -> 97 | RT1: =AVERAGE(RT2:RT1048576) -> 956.82181 | RU1: =_xlfn.VAR.P(RS2:RS1048576) -> 1.4435115 | RX1: =COUNT(RX3:RX1048576) -> 96 | RY1: =AVERAGE(RY2:RY1048576) -> 1019.2865 | RZ1: =_xlfn.VAR.P(RX2:RX1048576) -> 0.93359375 | SC1: =COUNT(SC3:SC1048576) -> 95 | SD1: =AVERAGE(SD2:SD1048576) -> 1020.9058 | SE1: =_xlfn.VAR.P(SC2:SC1048576) -> 1.0962881
A2: Order_Number | B2: Batch Size | C2: Duration | F2: Order_Number | G2: Batch Size | H2: Duration | K2: Order_Number | L2: Batch Size | M2: Duration | P2: Order_Number | Q2: Batch Size | R2: Duration | U2: Order_Number | V2: Batch Size | W2: Duration | Z2: Order_Number | AA2: Batch Size | AB2: Duration | AE2: Order_Number | AF2: Batch Size | AG2: Duration | AJ2: Order_Number | AK2: Batch Size | AL2: Duration | AO2: Order_Number | AP2: Batch Size | AQ2: Duration | AT2: Order_Number | AU2: Batch Size | AV2: Duration | AY2: Order_Number | AZ2: Batch Size | BA2: Duration | BD2: Order_Number | BE2: Batch Size | BF2: Duration | BI2: Order_Number | BJ2: Batch Size | BK2: Duration | BN2: Order_Number | BO2: Batch Size | BP2: Duration | BS2: Order_Number | BT2: Batch Size | BU2: Duration | BX2: Order_Number | BY2: Batch Size | BZ2: Duration | CC2: Order_Number | CD2: Batch Size | CE2: Duration | CH2: Order_Number | CI2: Batch Size | CJ2: Duration | CM2: Order_Number | CN2: Batch Size | CO2: Duration | CR2: Order_Number | CS2: Batch Size | CT2: Duration | CW2: Order_Number | CX2: Batch Size | CY2: Duration | DB2: Order_Number | DC2: Batch Size | DD2: Duration | DG2: Order_Number | DH2: Batch Size | DI2: Duration | DL2: Order_Number | DM2: Batch Size | DN2: Duration | DQ2: Order_Number | DR2: Batch Size | DS2: Duration | DV2: Order_Number | DW2: Batch Size | DX2: Duration | EA2: Order_Number | EB2: Batch Size | EC2: Duration | EF2: Order_Number | EG2: Batch Size | EH2: Duration | EK2: Order_Number | EL2: Batch Size | EM2: Duration | EP2: Order_Number | EQ2: Batch Size | ER2: Duration | EU2: Order_Number | EV2: Batch Size | EW2: Duration | EZ2: Order_Number | FA2: Batch Size | FB2: Duration | FE2: Order_Number | FF2: Batch Size | FG2: Duration | FJ2: Order_Number | FK2: Batch Size | FL2: Duration | FO2: Order_Number | FP2: Batch Size | FQ2: Duration | FT2: Order_Number | FU2: Batch Size | FV2: Duration | FY2: Order_Number | FZ2: Batch Size | GA2: Duration | GD2: Order_Number | GE2: Batch Size | GF2: Duration | GI2: Order_Number | GJ2: Batch Size | GK2: Duration | GN2: Order_Number | GO2: Batch Size | GP2: Duration | GS2: Order_Number | GT2: Batch Size | GU2: Duration | GX2: Order_Number | GY2: Batch Size | GZ2: Duration | HC2: Order_Number | HD2: Batch Size | HE2: Duration | HH2: Order_Number | HI2: Batch Size | HJ2: Duration | HM2: Order_Number | HN2: Batch Size | HO2: Duration | HR2: Order_Number | HS2: Batch Size | HT2: Duration | HW2: Order_Number | HX2: Batch Size | HY2: Duration | IB2: Order_Number | IC2: Batch Size | ID2: Duration | IG2: Order_Number | IH2: Batch Size | II2: Duration | IL2: Order_Number | IM2: Batch Size | IN2: Duration | IQ2: Order_Number | IR2: Batch Size | IS2: Duration | IV2: Order_Number | IW2: Batch Size | IX2: Duration | JA2: Order_Number | JB2: Batch Size | JC2: Duration | JF2: Order_Number | JG2: Batch Size | JH2: Duration | JK2: Order_Number | JL2: Batch Size | JM2: Duration | JP2: Order_Number | JQ2: Batch Size | JR2: Duration | JU2: Order_Number | JV2: Batch Size | JW2: Duration | JZ2: Order_Number | KA2: Batch Size | KB2: Duration | KE2: Order_Number | KF2: Batch Size | KG2: Duration | KJ2: Order_Number | KK2: Batch Size | KL2: Duration | KO2: Order_Number | KP2: Batch Size | KQ2: Duration | KT2: Order_Number | KU2: Batch Size | KV2: Duration | KY2: Order_Number | KZ2: Batch Size | LA2: Duration | LD2: Order_Number | LE2: Batch Size | LF2: Duration | LI2: Order_Number | LJ2: Batch Size | LK2: Duration | LN2: Order_Number | LO2: Batch Size | LP2: Duration | LS2: Order_Number | LT2: Batch Size | LU2: Duration | LX2: Order_Number | LY2: Batch Size | LZ2: Duration | MC2: Order_Number | MD2: Batch Size | ME2: Duration | MH2: Order_Number | MI2: Batch Size | MJ2: Duration | MM2: Order_Number | MN2: Batch Size | MO2: Duration | MR2: Order_Number | MS2: Batch Size | MT2: Duration | MW2: Order_Number | MX2: Batch Size | MY2: Duration | NB2: Order_Number | NC2: Batch Size | ND2: Duration | NG2: Order_Number | NH2: Batch Size | NI2: Duration | NL2: Order_Number | NM2: Batch Size | NN2: Duration | NQ2: Order_Number | NR2: Batch Size | NS2: Duration | NV2: Order_Number | NW2: Batch Size | NX2: Duration | OA2: Order_Number | OB2: Batch Size | OC2: Duration | OF2: Order_Number | OG2: Batch Size | OH2: Duration | OK2: Order_Number | OL2: Batch Size | OM2: Duration | OP2: Order_Number | OQ2: Batch Size | OR2: Duration | OU2: Order_Number | OV2: Batch Size | OW2: Duration | OZ2: Order_Number | PA2: Batch Size | PB2: Duration | PE2: Order_Number | PF2: Batch Size | PG2: Duration | PJ2: Order_Number | PK2: Batch Size | PL2: Duration | PO2: Order_Number | PP2: Batch Size | PQ2: Duration | PT2: Order_Number | PU2: Batch Size | PV2: Duration | PY2: Order_Number | PZ2: Batch Size | QA2: Duration | QD2: Order_Number | QE2: Batch Size | QF2: Duration | QI2: Order_Number | QJ2: Batch Size | QK2: Duration | QN2: Order_Number | QO2: Batch Size | QP2: Duration | QS2: Order_Number | QT2: Batch Size | QU2: Duration | QX2: Order_Number | QY2: Batch Size | QZ2: Duration | RC2: Order_Number | RD2: Batch Size | RE2: Duration | RH2: Order_Number | RI2: Batch Size | RJ2: Duration | RM2: Order_Number | RN2: Batch Size | RO2: Duration | RR2: Order_Number | RS2: Batch Size | RT2: Duration | RW2: Order_Number | RX2: Batch Size | RY2: Duration | SB2: Order_Number | SC2: Batch Size | SD2: Duration
A3: 1 | B3: 2 | C3: 71.248064 | D3: =C3/60 -> 1.1874677 | F3: 2 | G3: 4 | H3: 98.773427 | K3: 1 | L3: 3 | M3: 71.916871 | P3: 1 | Q3: 5 | R3: 87.66824 | U3: 1 | V3: 5 | W3: 96.142267 | Z3: 2 | AA3: 4 | AB3: 127.16967 | AE3: 1 | AF3: 4 | AG3: 94.789389 | AJ3: 1 | AK3: 3 | AL3: 84.860313 | AO3: 1 | AP3: 5 | AQ3: 108.38399 | AT3: 2 | AU3: 2 | AV3: 103.04948 | AY3: 1 | AZ3: 5 | BA3: 96.179602 | BD3: 2 | BE3: 4 | BF3: 126.80992 | BI3: 1 | BJ3: 3 | BK3: 86.869747 | BN3: 1 | BO3: 4 | BP3: 86.957224 | BS3: 1 | BT3: 2 | BU3: 86.276539 | BX3: 1 | BY3: 2 | BZ3: 74.722228 | CC3: 1 | CD3: 3 | CE3: 89.831184 | CH3: 1 | CI3: 4 | CJ3: 92.23067 | CM3: 1 | CN3: 2 | CO3: 64.404503 | CR3: 1 | CS3: 4 | CT3: 84.059043 | CW3: 1 | CX3: 3 | CY3: 76.052745 | DB3: 1 | DC3: 5 | DD3: 92.361897 | DG3: 1 | DH3: 5 | DI3: 101.52486 | DL3: 1 | DM3: 4 | DN3: 86.645006 | DQ3: 1 | DR3: 6 | DS3: 136.33985 | DV3: 1 | DW3: 5 | DX3: 93.543817 | EA3: 2 | EB3: 4 | EC3: 105.66351 | EF3: 1 | EG3: 6 | EH3: 99.217207 | EK3: 1 | EL3: 4 | EM3: 92.042481 | EP3: 1 | EQ3: 4 | ER3: 89.316744 | EU3: 1 | EV3: 4 | EW3: 111.06009 | EZ3: 1 | FA3: 1 | FB3: 65.598268 | FE3: 1 | FF3: 3 | FG3: 80.61833 | FJ3: 1 | FK3: 3 | FL3: 88.296362 | FO3: 1 | FP3: 4 | FQ3: 85.763916 | FT3: 1 | FU3: 5 | FV3: 91.449831 | FY3: 1 | FZ3: 3 | GA3: 76.477518 | GD3: 2 | GE3: 2 | GF3: 85.538869 | GI3: 1 | GJ3: 4 | GK3: 108.18699 | GN3: 1 | GO3: 4 | GP3: 84.958233 | GS3: 1 | GT3: 6 | GU3: 98.442478 | GX3: 1 | GY3: 5 | GZ3: 97.830643 | HC3: 1 | HD3: 6 | HE3: 119.69689 | HH3: 1 | HI3: 6 | HJ3: 134.61723 | HM3: 1 | HN3: 2 | HO3: 89.170098 | HR3: 1 | HS3: 3 | HT3: 87.28769 | HW3: 2 | HX3: 5 | HY3: 122.09659 | IB3: 1 | IC3: 3 | ID3: 89.496368 | IG3: 1 | IH3: 4 | II3: 83.50552 | IL3: 1 | IM3: 3 | IN3: 80.826031 | IQ3: 1 | IR3: 4 | IS3: 101.56817 | IV3: 1 | IW3: 3 | IX3: 83.230876 | JA3: 1 | JB3: 3 | JC3: 78.604047 | JF3: 1 | JG3: 4 | JH3: 82.844855 | JK3: 1 | JL3: 6 | JM3: 105.92159 | JP3: 1 | JQ3: 5 | JR3: 91.575363 | JU3: 1 | JV3: 5 | JW3: 114.53902 | JZ3: 1 | KA3: 4 | KB3: 95.11783 | KE3: 1 | KF3: 5 | KG3: 101.64301 | KJ3: 1 | KK3: 5 | KL3: 104.30062 | KO3: 1 | KP3: 3 | KQ3: 86.033265 | KT3: 1 | KU3: 4 | KV3: 109.73173 | KY3: 1 | KZ3: 4 | LA3: 95.756396 | LD3: 1 | LE3: 3 | LF3: 80.739827 | LI3: 1 | LJ3: 3 | LK3: 75.158059 | LN3: 1 | LO3: 3 | LP3: 78.134466 | LS3: 1 | LT3: 4 | LU3: 86.455395 | LX3: 1 | LY3: 4 | LZ3: 84.598601 | MC3: 1 | MD3: 3 | ME3: 77.548255 | MH3: 1 | MI3: 4 | MJ3: 94.000813 | MM3: 1 | MN3: 3 | MO3: 78.143883 | MR3: 1 | MS3: 6 | MT3: 134.91767 | MW3: 1 | MX3: 6 | MY3: 122.1545 | NB3: 1 | NC3: 5 | ND3: 108.16661 | NG3: 1 | NH3: 5 | NI3: 92.855773 | NL3: 1 | NM3: 3 | NN3: 84.486572 | NQ3: 1 | NR3: 2 | NS3: 74.591279 | NV3: 1 | NW3: 4 | NX3: 89.762013 | OA3: 1 | OB3: 4 | OC3: 91.737804 | OF3: 1 | OG3: 5 | OH3: 92.696497 | OK3: 1 | OL3: 5 | OM3: 96.640935 | OP3: 1 | OQ3: 2 | OR3: 75.414908 | OU3: 1 | OV3: 3 | OW3: 78.640948 | OZ3: 1 | PA3: 3 | PB3: 109.76362 | PE3: 1 | PF3: 4 | PG3: 85.472922 | PJ3: 1 | PK3: 5 | PL3: 87.363982 | PO3: 1 | PP3: 4 | PQ3: 86.971025 | PT3: 1 | PU3: 6 | PV3: 124.81614 | PY3: 1 | PZ3: 5 | QA3: 115.11243 | QD3: 3 | QE3: 3 | QF3: 111.32244 | QI3: 1 | QJ3: 5 | QK3: 93.92795 | QN3: 1 | QO3: 4 | QP3: 89.01445 | QS3: 1 | QT3: 4 | QU3: 89.582013 | QX3: 1 | QY3: 5 | QZ3: 85.615537 | RC3: 1 | RD3: 3 | RE3: 83.356432 | RH3: 1 | RI3: 4 | RJ3: 92.772482 | RM3: 1 | RN3: 4 | RO3: 89.317367 | RR3: 1 | RS3: 2 | RT3: 74.102321 | RW3: 1 | RX3: 4 | RY3: 86.45609 | SB3: 1 | SC3: 3 | SD3: 79.250308
A4: 1 | B4: 2 | C4: 71.248064 | D4: =C4/60 -> 1.1874677 | F4: 2 | G4: 4 | H4: 98.773427 | K4: 1 | L4: 3 | M4: 71.916871 | P4: 1 | Q4: 5 | R4: 87.66824 | U4: 1 | V4: 5 | W4: 96.142267 | Z4: 2 | AA4: 4 | AB4: 127.16967 | AE4: 1 | AF4: 4 | AG4: 94.789389 | AJ4: 1 | AK4: 3 | AL4: 84.860313 | AO4: 1 | AP4: 5 | AQ4: 108.38399 | AT4: 2 | AU4: 2 | AV4: 103.04948 | AY4: 1 | AZ4: 5 | BA4: 96.179602 | BD4: 2 | BE4: 4 | BF4: 126.80992 | BI4: 1 | BJ4: 3 | BK4: 86.869747 | BN4: 1 | BO4: 4 | BP4: 86.957224 | BS4: 1 | BT4: 2 | BU4: 86.276539 | BX4: 1 | BY4: 2 | BZ4: 74.722228 | CC4: 1 | CD4: 3 | CE4: 89.831184 | CH4: 1 | CI4: 4 | CJ4: 92.23067 | CM4: 1 | CN4: 2 | CO4: 64.404503 | CR4: 1 | CS4: 4 | CT4: 84.059043 | CW4: 1 | CX4: 3 | CY4: 76.052745 | DB4: 1 | DC4: 5 | DD4: 92.361897 | DG4: 1 | DH4: 5 | DI4: 101.52486 | DL4: 1 | DM4: 4 | DN4: 86.645006 | DQ4: 1 | DR4: 6 | DS4: 136.33985 | DV4: 1 | DW4: 5 | DX4: 93.543817 | EA4: 2 | EB4: 4 | EC4: 105.66351 | EF4: 1 | EG4: 6 | EH4: 99.217207 | EK4: 1 | EL4: 4 | EM4: 92.042481 | EP4: 1 | EQ4: 4 | ER4: 89.316744 | EU4: 1 | EV4: 4 | EW4: 111.06009 | EZ4: 2 | FA4: 5 | FB4: 98.98782 | FE4: 1 | FF4: 3 | FG4: 80.61833 | FJ4: 1 | FK4: 3 | FL4: 88.296362 | FO4: 1 | FP4: 4 | FQ4: 85.763916 | FT4: 1 | FU4: 5 | FV4: 91.449831 | FY4: 1 | FZ4: 3 | GA4: 76.477518 | GD4: 2 | GE4: 2 | GF4: 85.538869 | GI4: 1 | GJ4: 4 | GK4: 108.18699 | GN4: 1 | GO4: 4 | GP4: 84.958233 | GS4: 1 | GT4: 6 | GU4: 98.442478 | GX4: 1 | GY4: 5 | GZ4: 97.830643 | HC4: 1 | HD4: 6 | HE4: 119.69689 | HH4: 1 | HI4: 6 | HJ4: 134.61723 | HM4: 1 | HN4: 2 | HO4: 89.170098 | HR4: 1 | HS4: 3 | HT4: 87.28769 | HW4: 2 | HX4: 5 | HY4: 122.09659 | IB4: 1 | IC4: 3 | ID4: 89.496368 | IG4: 1 | IH4: 4 | II4: 83.50552 | IL4: 1 | IM4: 3 | IN4: 80.826031 | IQ4: 1 | IR4: 4 | IS4: 101.56817 | IV4: 1 | IW4: 3 | IX4: 83.230876 | JA4: 1 | JB4: 3 | JC4: 78.604047 | JF4: 1 | JG4: 4 | JH4: 82.844855 | JK4: 1 | JL4: 6 | JM4: 105.92159 | JP4: 1 | JQ4: 5 | JR4: 91.575363 | JU4: 1 | JV4: 5 | JW4: 114.53902 | JZ4: 1 | KA4: 4 | KB4: 95.11783 | KE4: 1 | KF4: 5 | KG4: 101.64301 | KJ4: 1 | KK4: 5 | KL4: 104.30062 | KO4: 1 | KP4: 3 | KQ4: 86.033265 | KT4: 1 | KU4: 4 | KV4: 109.73173 | KY4: 1 | KZ4: 4 | LA4: 95.756396 | LD4: 1 | LE4: 3 | LF4: 80.739827 | LI4: 1 | LJ4: 3 | LK4: 75.158059 | LN4: 1 | LO4: 3 | LP4: 78.134466 | LS4: 1 | LT4: 4 | LU4: 86.455395 | LX4: 1 | LY4: 4 | LZ4: 84.598601 | MC4: 1 | MD4: 3 | ME4: 77.548255 | MH4: 1 | MI4: 4 | MJ4: 94.000813 | MM4: 1 | MN4: 3 | MO4: 78.143883 | MR4: 1 | MS4: 6 | MT4: 134.91767 | MW4: 1 | MX4: 6 | MY4: 122.1545 | NB4: 1 | NC4: 5 | ND4: 108.16661 | NG4: 1 | NH4: 5 | NI4: 92.855773 | NL4: 1 | NM4: 3 | NN4: 84.486572 | NQ4: 1 | NR4: 2 | NS4: 74.591279 | NV4: 1 | NW4: 4 | NX4: 89.762013 | OA4: 1 | OB4: 4 | OC4: 91.737804 | OF4: 1 | OG4: 5 | OH4: 92.696497 | OK4: 1 | OL4: 5 | OM4: 96.640935 | OP4: 1 | OQ4: 2 | OR4: 75.414908 | OU4: 1 | OV4: 3 | OW4: 78.640948 | OZ4: 1 | PA4: 3 | PB4: 109.76362 | PE4: 1 | PF4: 4 | PG4: 85.472922 | PJ4: 1 | PK4: 5 | PL4: 87.363982 | PO4: 1 | PP4: 4 | PQ4: 86.971025 | PT4: 1 | PU4: 6 | PV4: 124.81614 | PY4: 1 | PZ4: 5 | QA4: 115.11243 | QD4: 3 | QE4: 3 | QF4: 111.32244 | QI4: 1 | QJ4: 5 | QK4: 93.92795 | QN4: 1 | QO4: 4 | QP4: 89.01445 | QS4: 1 | QT4: 4 | QU4: 89.582013 | QX4: 1 | QY4: 5 | QZ4: 85.615537 | RC4: 1 | RD4: 3 | RE4: 83.356432 | RH4: 1 | RI4: 4 | RJ4: 92.772482 | RM4: 1 | RN4: 4 | RO4: 89.317367 | RR4: 1 | RS4: 2 | RT4: 74.102321 | RW4: 1 | RX4: 4 | RY4: 86.45609 | SB4: 1 | SC4: 3 | SD4: 79.250308
A5: 2 | B5: 4 | C5: 104.39498 | D5: =C5/60 -> 1.7399163 | F5: 2 | G5: 4 | H5: 98.773427 | K5: 1 | L5: 3 | M5: 71.916871 | P5: 1 | Q5: 5 | R5: 87.66824 | U5: 1 | V5: 5 | W5: 96.142267 | Z5: 2 | AA5: 4 | AB5: 127.16967 | AE5: 1 | AF5: 4 | AG5: 94.789389 | AJ5: 1 | AK5: 3 | AL5: 84.860313 | AO5: 1 | AP5: 5 | AQ5: 108.38399 | AT5: 1 | AU5: 6 | AV5: 116.51136 | AY5: 1 | AZ5: 5 | BA5: 96.179602 | BD5: 2 | BE5: 4 | BF5: 126.80992 | BI5: 1 | BJ5: 3 | BK5: 86.869747 | BN5: 1 | BO5: 4 | BP5: 86.957224 | BS5: 2 | BT5: 5 | BU5: 130.56449 | BX5: 2 | BY5: 4 | BZ5: 117.52048 | CC5: 1 | CD5: 3 | CE5: 89.831184 | CH5: 1 | CI5: 4 | CJ5: 92.23067 | CM5: 2 | CN5: 5 | CO5: 116.51496 | CR5: 1 | CS5: 4 | CT5: 84.059043 | CW5: 1 | CX5: 3 | CY5: 76.052745 | DB5: 1 | DC5: 5 | DD5: 92.361897 | DG5: 1 | DH5: 5 | DI5: 101.52486 | DL5: 1 | DM5: 4 | DN5: 86.645006 | DQ5: 1 | DR5: 6 | DS5: 136.33985 | DV5: 1 | DW5: 5 | DX5: 93.543817 | EA5: 2 | EB5: 4 | EC5: 105.66351 | EF5: 1 | EG5: 6 | EH5: 99.217207 | EK5: 1 | EL5: 4 | EM5: 92.042481 | EP5: 1 | EQ5: 4 | ER5: 89.316744 | EU5: 1 | EV5: 4 | EW5: 111.06009 | EZ5: 2 | FA5: 5 | FB5: 98.98782 | FE5: 1 | FF5: 3 | FG5: 80.61833 | FJ5: 1 | FK5: 3 | FL5: 88.296362 | FO5: 1 | FP5: 4 | FQ5: 85.763916 | FT5: 1 | FU5: 5 | FV5: 91.449831 | FY5: 1 | FZ5: 3 | GA5: 76.477518 | GD5: 1 | GE5: 4 | GF5: 106.2743 | GI5: 1 | GJ5: 4 | GK5: 108.18699 | GN5: 1 | GO5: 4 | GP5: 84.958233 | GS5: 1 | GT5: 6 | GU5: 98.442478 | GX5: 1 | GY5: 5 | GZ5: 97.830643 | HC5: 1 | HD5: 6 | HE5: 119.69689 | HH5: 1 | HI5: 6 | HJ5: 134.61723 | HM5: 2 | HN5: 5 | HO5: 112.11985 | HR5: 1 | HS5: 3 | HT5: 87.28769 | HW5: 2 | HX5: 5 | HY5: 122.09659 | IB5: 1 | IC5: 3 | ID5: 89.496368 | IG5: 1 | IH5: 4 | II5: 83.50552 | IL5: 1 | IM5: 3 | IN5: 80.826031 | IQ5: 1 | IR5: 4 | IS5: 101.56817 | IV5: 1 | IW5: 3 | IX5: 83.230876 | JA5: 1 | JB5: 3 | JC5: 78.604047 | JF5: 1 | JG5: 4 | JH5: 82.844855 | JK5: 1 | JL5: 6 | JM5: 105.92159 | JP5: 1 | JQ5: 5 | JR5: 91.575363 | JU5: 1 | JV5: 5 | JW5: 114.53902 | JZ5: 1 | KA5: 4 | KB5: 95.11783 | KE5: 1 | KF5: 5 | KG5: 101.64301 | KJ5: 1 | KK5: 5 | KL5: 104.30062 | KO5: 1 | KP5: 3 | KQ5: 86.033265 | KT5: 1 | KU5: 4 | KV5: 109.73173 | KY5: 1 | KZ5: 4 | LA5: 95.756396 | LD5: 1 | LE5: 3 | LF5: 80.739827 | LI5: 1 | LJ5: 3 | LK5: 75.158059 | LN5: 1 | LO5: 3 | LP5: 78.134466 | LS5: 1 | LT5: 4 | LU5: 86.455395 | LX5: 1 | LY5: 4 | LZ5: 84.598601 | MC5: 1 | MD5: 3 | ME5: 77.548255 | MH5: 1 | MI5: 4 | MJ5: 94.000813 | MM5: 1 | MN5: 3 | MO5: 78.143883 | MR5: 1 | MS5: 6 | MT5: 134.91767 | MW5: 1 | MX5: 6 | MY5: 122.1545 | NB5: 1 | NC5: 5 | ND5: 108.16661 | NG5: 1 | NH5: 5 | NI5: 92.855773 | NL5: 1 | NM5: 3 | NN5: 84.486572 | NQ5: 2 | NR5: 2 | NS5: 86.754117 | NV5: 1 | NW5: 4 | NX5: 89.762013 | OA5: 1 | OB5: 4 | OC5: 91.737804 | OF5: 1 | OG5: 5 | OH5: 92.696497 | OK5: 1 | OL5: 5 | OM5: 96.640935 | OP5: 2 | OQ5: 4 | OR5: 127.06196 | OU5: 1 | OV5: 3 | OW5: 78.640948 | OZ5: 1 | PA5: 3 | PB5: 109.76362 | PE5: 1 | PF5: 4 | PG5: 85.472922 | PJ5: 1 | PK5: 5 | PL5: 87.363982 | PO5: 1 | PP5: 4 | PQ5: 86.971025 | PT5: 1 | PU5: 6 | PV5: 124.81614 | PY5: 1 | PZ5: 5 | QA5: 115.11243 | QD5: 3 | QE5: 3 | QF5: 111.32244 | QI5: 1 | QJ5: 5 | QK5: 93.92795 | QN5: 1 | QO5: 4 | QP5: 89.01445 | QS5: 1 | QT5: 4 | QU5: 89.582013 | QX5: 1 | QY5: 5 | QZ5: 85.615537 | RC5: 1 | RD5: 3 | RE5: 83.356432 | RH5: 1 | RI5: 4 | RJ5: 92.772482 | RM5: 1 | RN5: 4 | RO5: 89.317367 | RR5: 2 | RS5: 4 | RT5: 98.829901 | RW5: 1 | RX5: 4 | RY5: 86.45609 | SB5: 1 | SC5: 3 | SD5: 79.250308
A6: 2 | B6: 4 | C6: 104.39498 | D6: =C6/60 -> 1.7399163 | F6: 2 | G6: 4 | H6: 98.773427 | K6: 2 | L6: 4 | M6: 82.774804 | P6: 1 | Q6: 5 | R6: 87.66824 | U6: 1 | V6: 5 | W6: 96.142267 | Z6: 2 | AA6: 4 | AB6: 127.16967 | AE6: 1 | AF6: 4 | AG6: 94.789389 | AJ6: 2 | AK6: 4 | AL6: 103.69303 | AO6: 1 | AP6: 5 | AQ6: 108.38399 | AT6: 1 | AU6: 6 | AV6: 116.51136 | AY6: 1 | AZ6: 5 | BA6: 96.179602 | BD6: 2 | BE6: 4 | BF6: 126.80992 | BI6: 2 | BJ6: 3 | BK6: 104.74053 | BN6: 1 | BO6: 4 | BP6: 86.957224 | BS6: 2 | BT6: 5 | BU6: 130.56449 | BX6: 2 | BY6: 4 | BZ6: 117.52048 | CC6: 2 | CD6: 5 | CE6: 121.58882 | CH6: 1 | CI6: 4 | CJ6: 92.23067 | CM6: 2 | CN6: 5 | CO6: 116.51496 | CR6: 1 | CS6: 4 | CT6: 84.059043 | CW6: 2 | CX6: 4 | CY6: 90.591076 | DB6: 1 | DC6: 5 | DD6: 92.361897 | DG6: 1 | DH6: 5 | DI6: 101.52486 | DL6: 1 | DM6: 4 | DN6: 86.645006 | DQ6: 1 | DR6: 6 | DS6: 136.33985 | DV6: 1 | DW6: 5 | DX6: 93.543817 | EA6: 2 | EB6: 4 | EC6: 105.66351 | EF6: 1 | EG6: 6 | EH6: 99.217207 | EK6: 1 | EL6: 4 | EM6: 92.042481 | EP6: 1 | EQ6: 4 | ER6: 89.316744 | EU6: 1 | EV6: 4 | EW6: 111.06009 | EZ6: 2 | FA6: 5 | FB6: 98.98782 | FE6: 2 | FF6: 4 | FG6: 125.24384 | FJ6: 2 | FK6: 5 | FL6: 140.03749 | FO6: 1 | FP6: 4 | FQ6: 85.763916 | FT6: 1 | FU6: 5 | FV6: 91.449831 | FY6: 2 | FZ6: 5 | GA6: 95.622905 | GD6: 1 | GE6: 4 | GF6: 106.2743 | GI6: 1 | GJ6: 4 | GK6: 108.18699 | GN6: 1 | GO6: 4 | GP6: 84.958233 | GS6: 1 | GT6: 6 | GU6: 98.442478 | GX6: 1 | GY6: 5 | GZ6: 97.830643 | HC6: 1 | HD6: 6 | HE6: 119.69689 | HH6: 1 | HI6: 6 | HJ6: 134.61723 | HM6: 2 | HN6: 5 | HO6: 112.11985 | HR6: 2 | HS6: 3 | HT6: 101.12008 | HW6: 2 | HX6: 5 | HY6: 122.09659 | IB6: 2 | IC6: 2 | ID6: 91.568075 | IG6: 1 | IH6: 4 | II6: 83.50552 | IL6: 2 | IM6: 1 | IN6: 100.76458 | IQ6: 1 | IR6: 4 | IS6: 101.56817 | IV6: 3 | IW6: 4 | IX6: 155.97292 | JA6: 2 | JB6: 4 | JC6: 105.13048 | JF6: 1 | JG6: 4 | JH6: 82.844855 | JK6: 1 | JL6: 6 | JM6: 105.92159 | JP6: 1 | JQ6: 5 | JR6: 91.575363 | JU6: 1 | JV6: 5 | JW6: 114.53902 | JZ6: 1 | KA6: 4 | KB6: 95.11783 | KE6: 1 | KF6: 5 | KG6: 101.64301 | KJ6: 1 | KK6: 5 | KL6: 104.30062 | KO6: 3 | KP6: 5 | KQ6: 131.66618 | KT6: 1 | KU6: 4 | KV6: 109.73173 | KY6: 1 | KZ6: 4 | LA6: 95.756396 | LD6: 2 | LE6: 5 | LF6: 115.60868 | LI6: 2 | LJ6: 3 | LK6: 96.675488 | LN6: 2 | LO6: 5 | LP6: 134.86583 | LS6: 1 | LT6: 4 | LU6: 86.455395 | LX6: 1 | LY6: 4 | LZ6: 84.598601 | MC6: 3 | MD6: 3 | ME6: 102.54764 | MH6: 1 | MI6: 4 | MJ6: 94.000813 | MM6: 3 | MN6: 3 | MO6: 106.79994 | MR6: 1 | MS6: 6 | MT6: 134.91767 | MW6: 1 | MX6: 6 | MY6: 122.1545 | NB6: 1 | NC6: 5 | ND6: 108.16661 | NG6: 1 | NH6: 5 | NI6: 92.855773 | NL6: 3 | NM6: 5 | NN6: 132.43491 | NQ6: 2 | NR6: 2 | NS6: 86.754117 | NV6: 1 | NW6: 4 | NX6: 89.762013 | OA6: 1 | OB6: 4 | OC6: 91.737804 | OF6: 1 | OG6: 5 | OH6: 92.696497 | OK6: 1 | OL6: 5 | OM6: 96.640935 | OP6: 2 | OQ6: 4 | OR6: 127.06196 | OU6: 2 | OV6: 5 | OW6: 114.87672 | OZ6: 2 | PA6: 6 | PB6: 121.13906 | PE6: 1 | PF6: 4 | PG6: 85.472922 | PJ6: 1 | PK6: 5 | PL6: 87.363982 | PO6: 1 | PP6: 4 | PQ6: 86.971025 | PT6: 1 | PU6: 6 | PV6: 124.81614 | PY6: 1 | PZ6: 5 | QA6: 115.11243 | QD6: 2 | QE6: 3 | QF6: 111.92657 | QI6: 1 | QJ6: 5 | QK6: 93.92795 | QN6: 1 | QO6: 4 | QP6: 89.01445 | QS6: 1 | QT6: 4 | QU6: 89.582013 | QX6: 1 | QY6: 5 | QZ6: 85.615537 | RC6: 2 | RD6: 4 | RE6: 111.28778 | RH6: 1 | RI6: 4 | RJ6: 92.772482 | RM6: 1 | RN6: 4 | RO6: 89.317367 | RR6: 2 | RS6: 4 | RT6: 98.829901 | RW6: 1 | RX6: 4 | RY6: 86.45609 | SB6: 2 | SC6: 3 | SD6: 103.71303
A7: 2 | B7: 4 | C7: 104.39498 | D7: =C7/60 -> 1.7399163 | F7: 1 | G7: 2 | H7: 114.38403 | K7: 2 | L7: 4 | M7: 82.774804 | P7: 1 | Q7: 5 | R7: 87.66824 | U7: 1 | V7: 5 | W7: 96.142267 | Z7: 1 | AA7: 6 | AB7: 137.28697 | AE7: 3 | AF7: 2 | AG7: 112.94139 | AJ7: 2 | AK7: 4 | AL7: 103.69303 | AO7: 1 | AP7: 5 | AQ7: 108.38399 | AT7: 1 | AU7: 6 | AV7: 116.51136 | AY7: 1 | AZ7: 5 | BA7: 96.179602 | BD7: 1 | BE7: 6 | BF7: 157.44381 | BI7: 2 | BJ7: 3 | BK7: 104.74053 | BN7: 2 | BO7: 5 | BP7: 143.79959 | BS7: 2 | BT7: 5 | BU7: 130.56449 | BX7: 2 | BY7: 4 | BZ7: 117.52048 | CC7: 2 | CD7: 5 | CE7: 121.58882 | CH7: 2 | CI7: 4 | CJ7: 135.53507 | CM7: 2 | CN7: 5 | CO7: 116.51496 | CR7: 2 | CS7: 3 | CT7: 85.888879 | CW7: 2 | CX7: 4 | CY7: 90.591076 | DB7: 1 | DC7: 5 | DD7: 92.361897 | DG7: 1 | DH7: 5 | DI7: 101.52486 | DL7: 3 | DM7: 2 | DN7: 124.30513 | DQ7: 1 | DR7: 6 | DS7: 136.33985 | DV7: 1 | DW7: 5 | DX7: 93.543817 | EA7: 1 | EB7: 4 | EC7: 117.12809 | EF7: 1 | EG7: 6 | EH7: 99.217207 | EK7: 2 | EL7: 4 | EM7: 126.32168 | EP7: 3 | EQ7: 1 | ER7: 93.679421 | EU7: 2 | EV7: 3 | EW7: 125.85755 | EZ7: 2 | FA7: 5 | FB7: 98.98782 | FE7: 2 | FF7: 4 | FG7: 125.24384 | FJ7: 2 | FK7: 5 | FL7: 140.03749 | FO7: 2 | FP7: 3 | FQ7: 110.01715 | FT7: 1 | FU7: 5 | FV7: 91.449831 | FY7: 2 | FZ7: 5 | GA7: 95.622905 | GD7: 1 | GE7: 4 | GF7: 106.2743 | GI7: 2 | GJ7: 3 | GK7: 126.80061 | GN7: 2 | GO7: 3 | GP7: 99.376385 | GS7: 1 | GT7: 6 | GU7: 98.442478 | GX7: 1 | GY7: 5 | GZ7: 97.830643 | HC7: 1 | HD7: 6 | HE7: 119.69689 | HH7: 1 | HI7: 6 | HJ7: 134.61723 | HM7: 2 | HN7: 5 | HO7: 112.11985 | HR7: 2 | HS7: 3 | HT7: 101.12008 | HW7: 2 | HX7: 5 | HY7: 122.09659 | IB7: 2 | IC7: 2 | ID7: 91.568075 | IG7: 2 | IH7: 4 | II7: 114.68066 | IL7: 3 | IM7: 6 | IN7: 144.25202 | IQ7: 2 | IR7: 6 | IS7: 128.79624 | IV7: 3 | IW7: 4 | IX7: 155.97292 | JA7: 2 | JB7: 4 | JC7: 105.13048 | JF7: 3 | JG7: 3 | JH7: 117.13713 | JK7: 1 | JL7: 6 | JM7: 105.92159 | JP7: 1 | JQ7: 5 | JR7: 91.575363 | JU7: 1 | JV7: 5 | JW7: 114.53902 | JZ7: 3 | KA7: 2 | KB7: 111.02697 | KE7: 1 | KF7: 5 | KG7: 101.64301 | KJ7: 1 | KK7: 5 | KL7: 104.30062 | KO7: 3 | KP7: 5 | KQ7: 131.66618 | KT7: 2 | KU7: 5 | KV7: 157.38368 | KY7: 2 | KZ7: 5 | LA7: 129.02198 | LD7: 2 | LE7: 5 | LF7: 115.60868 | LI7: 2 | LJ7: 3 | LK7: 96.675488 | LN7: 2 | LO7: 5 | LP7: 134.86583 | LS7: 2 | LT7: 1 | LU7: 93.425258 | LX7: 2 | LY7: 4 | LZ7: 112.01035 | MC7: 3 | MD7: 3 | ME7: 102.54764 | MH7: 2 | MI7: 5 | MJ7: 107.15084 | MM7: 3 | MN7: 3 | MO7: 106.79994 | MR7: 1 | MS7: 6 | MT7: 134.91767 | MW7: 1 | MX7: 6 | MY7: 122.1545 | NB7: 1 | NC7: 5 | ND7: 108.16661 | NG7: 1 | NH7: 5 | NI7: 92.855773 | NL7: 3 | NM7: 5 | NN7: 132.43491 | NQ7: 3 | NR7: 5 | NS7: 110.22476 | NV7: 2 | NW7: 4 | NX7: 114.43544 | OA7: 2 | OB7: 2 | OC7: 103.37615 | OF7: 1 | OG7: 5 | OH7: 92.696497 | OK7: 1 | OL7: 5 | OM7: 96.640935 | OP7: 2 | OQ7: 4 | OR7: 127.06196 | OU7: 2 | OV7: 5 | OW7: 114.87672 | OZ7: 2 | PA7: 6 | PB7: 121.13906 | PE7: 2 | PF7: 3 | PG7: 111.38287 | PJ7: 1 | PK7: 5 | PL7: 87.363982 | PO7: 2 | PP7: 3 | PQ7: 86.989163 | PT7: 1 | PU7: 6 | PV7: 124.81614 | PY7: 1 | PZ7: 5 | QA7: 115.11243 | QD7: 2 | QE7: 3 | QF7: 111.92657 | QI7: 1 | QJ7: 5 | QK7: 93.92795 | QN7: 2 | QO7: 4 | QP7: 111.05031 | QS7: 2 | QT7: 4 | QU7: 116.0632 | QX7: 1 | QY7: 5 | QZ7: 85.615537 | RC7: 2 | RD7: 4 | RE7: 111.28778 | RH7: 3 | RI7: 2 | RJ7: 113.36944 | RM7: 2 | RN7: 3 | RO7: 114.20306 | RR7: 2 | RS7: 4 | RT7: 98.829901 | RW7: 2 | RX7: 6 | RY7: 131.23324 | SB7: 2 | SC7: 3 | SD7: 103.71303
A8: 2 | B8: 4 | C8: 104.39498 | D8: =C8/60 -> 1.7399163 | F8: 1 | G8: 2 | H8: 114.38403 | K8: 2 | L8: 4 | M8: 82.774804 | P8: 2 | Q8: 5 | R8: 136.44975 | U8: 3 | V8: 4 | W8: 134.67898 | Z8: 1 | AA8: 6 | AB8: 137.28697 | AE8: 3 | AF8: 2 | AG8: 112.94139 | AJ8: 2 | AK8: 4 | AL8: 103.69303 | AO8: 2 | AP8: 3 | AQ8: 113.99055 | AT8: 1 | AU8: 6 | AV8: 116.51136 | AY8: 2 | AZ8: 4 | BA8: 143.76351 | BD8: 1 | BE8: 6 | BF8: 157.44381 | BI8: 2 | BJ8: 3 | BK8: 104.74053 | BN8: 2 | BO8: 5 | BP8: 143.79959 | BS8: 2 | BT8: 5 | BU8: 130.56449 | BX8: 2 | BY8: 4 | BZ8: 117.52048 | CC8: 2 | CD8: 5 | CE8: 121.58882 | CH8: 2 | CI8: 4 | CJ8: 135.53507 | CM8: 2 | CN8: 5 | CO8: 116.51496 | CR8: 2 | CS8: 3 | CT8: 85.888879 | CW8: 2 | CX8: 4 | CY8: 90.591076 | DB8: 2 | DC8: 5 | DD8: 120.10189 | DG8: 2 | DH8: 5 | DI8: 123.19905 | DL8: 3 | DM8: 2 | DN8: 124.30513 | DQ8: 1 | DR8: 6 | DS8: 136.33985 | DV8: 2 | DW8: 5 | DX8: 123.68225 | EA8: 1 | EB8: 4 | EC8: 117.12809 | EF8: 1 | EG8: 6 | EH8: 99.217207 | EK8: 2 | EL8: 4 | EM8: 126.32168 | EP8: 2 | EQ8: 3 | ER8: 119.25079 | EU8: 2 | EV8: 3 | EW8: 125.85755 | EZ8: 2 | FA8: 5 | FB8: 98.98782 | FE8: 2 | FF8: 4 | FG8: 125.24384 | FJ8: 2 | FK8: 5 | FL8: 140.03749 | FO8: 2 | FP8: 3 | FQ8: 110.01715 | FT8: 2 | FU8: 5 | FV8: 152.44014 | FY8: 2 | FZ8: 5 | GA8: 95.622905 | GD8: 1 | GE8: 4 | GF8: 106.2743 | GI8: 2 | GJ8: 3 | GK8: 126.80061 | GN8: 2 | GO8: 3 | GP8: 99.376385 | GS8: 1 | GT8: 6 | GU8: 98.442478 | GX8: 2 | GY8: 4 | GZ8: 139.78651 | HC8: 1 | HD8: 6 | HE8: 119.69689 | HH8: 1 | HI8: 6 | HJ8: 134.61723 | HM8: 2 | HN8: 5 | HO8: 112.11985 | HR8: 2 | HS8: 3 | HT8: 101.12008 | HW8: 1 | HX8: 4 | HY8: 143.4896 | IB8: 3 | IC8: 3 | ID8: 103.50059 | IG8: 2 | IH8: 4 | II8: 114.68066 | IL8: 3 | IM8: 6 | IN8: 144.25202 | IQ8: 2 | IR8: 6 | IS8: 128.79624 | IV8: 3 | IW8: 4 | IX8: 155.97292 | JA8: 2 | JB8: 4 | JC8: 105.13048 | JF8: 3 | JG8: 3 | JH8: 117.13713 | JK8: 1 | JL8: 6 | JM8: 105.92159 | JP8: 2 | JQ8: 5 | JR8: 115.44246 | JU8: 2 | JV8: 3 | JW8: 124.10657 | JZ8: 3 | KA8: 2 | KB8: 111.02697 | KE8: 2 | KF8: 5 | KG8: 123.16746 | KJ8: 2 | KK8: 2 | KL8: 112.69577 | KO8: 3 | KP8: 5 | KQ8: 131.66618 | KT8: 2 | KU8: 5 | KV8: 157.38368 | KY8: 2 | KZ8: 5 | LA8: 129.02198 | LD8: 2 | LE8: 5 | LF8: 115.60868 | LI8: 2 | LJ8: 3 | LK8: 96.675488 | LN8: 2 | LO8: 5 | LP8: 134.86583 | LS8: 3 | LT8: 5 | LU8: 120.47666 | LX8: 2 | LY8: 4 | LZ8: 112.01035 | MC8: 3 | MD8: 3 | ME8: 102.54764 | MH8: 2 | MI8: 5 | MJ8: 107.15084 | MM8: 3 | MN8: 3 | MO8: 106.79994 | MR8: 1 | MS8: 6 | MT8: 134.91767 | MW8: 1 | MX8: 6 | MY8: 122.1545 | NB8: 2 | NC8: 6 | ND8: 132.7448 | NG8: 2 | NH8: 2 | NI8: 99.408219 | NL8: 3 | NM8: 5 | NN8: 132.43491 | NQ8: 3 | NR8: 5 | NS8: 110.22476 | NV8: 2 | NW8: 4 | NX8: 114.43544 | OA8: 2 | OB8: 2 | OC8: 103.37615 | OF8: 2 | OG8: 5 | OH8: 130.47803 | OK8: 3 | OL8: 5 | OM8: 163.2878 | OP8: 2 | OQ8: 4 | OR8: 127.06196 | OU8: 2 | OV8: 5 | OW8: 114.87672 | OZ8: 2 | PA8: 6 | PB8: 121.13906 | PE8: 2 | PF8: 3 | PG8: 111.38287 | PJ8: 3 | PK8: 4 | PL8: 110.4467 | PO8: 2 | PP8: 3 | PQ8: 86.989163 | PT8: 1 | PU8: 6 | PV8: 124.81614 | PY8: 2 | PZ8: 4 | QA8: 121.30629 | QD8: 2 | QE8: 3 | QF8: 111.92657 | QI8: 2 | QJ8: 5 | QK8: 147.10744 | QN8: 2 | QO8: 4 | QP8: 111.05031 | QS8: 2 | QT8: 4 | QU8: 116.0632 | QX8: 2 | QY8: 5 | QZ8: 121.58412 | RC8: 2 | RD8: 4 | RE8: 111.28778 | RH8: 3 | RI8: 2 | RJ8: 113.36944 | RM8: 2 | RN8: 3 | RO8: 114.20306 | RR8: 2 | RS8: 4 | RT8: 98.829901 | RW8: 2 | RX8: 6 | RY8: 131.23324 | SB8: 2 | SC8: 3 | SD8: 103.71303
A9: 3 | B9: 5 | C9: 144.69492 | D9: =C9/60 -> 2.411582 | F9: 3 | G9: 4 | H9: 128.38357 | K9: 2 | L9: 4 | M9: 82.774804 | P9: 2 | Q9: 5 | R9: 136.44975 | U9: 3 | V9: 4 | W9: 134.67898 | Z9: 1 | AA9: 6 | AB9: 137.28697 | AE9: 2 | AF9: 5 | AG9: 142.17217 | AJ9: 2 | AK9: 4 | AL9: 103.69303 | AO9: 2 | AP9: 3 | AQ9: 113.99055 | AT9: 1 | AU9: 6 | AV9: 116.51136 | AY9: 2 | AZ9: 4 | BA9: 143.76351 | BD9: 1 | BE9: 6 | BF9: 157.44381 | BI9: 4 | BJ9: 4 | BK9: 125.00477 | BN9: 2 | BO9: 5 | BP9: 143.79959 | BS9: 2 | BT9: 5 | BU9: 130.56449 | BX9: 3 | BY9: 3 | BZ9: 120.57893 | CC9: 2 | CD9: 5 | CE9: 121.58882 | CH9: 2 | CI9: 4 | CJ9: 135.53507 | CM9: 2 | CN9: 5 | CO9: 116.51496 | CR9: 2 | CS9: 3 | CT9: 85.888879 | CW9: 2 | CX9: 4 | CY9: 90.591076 | DB9: 2 | DC9: 5 | DD9: 120.10189 | DG9: 2 | DH9: 5 | DI9: 123.19905 | DL9: 2 | DM9: 4 | DN9: 128.6718 | DQ9: 3 | DR9: 5 | DS9: 174.75679 | DV9: 2 | DW9: 5 | DX9: 123.68225 | EA9: 1 | EB9: 4 | EC9: 117.12809 | EF9: 2 | EG9: 2 | EH9: 108.78749 | EK9: 2 | EL9: 4 | EM9: 126.32168 | EP9: 2 | EQ9: 3 | ER9: 119.25079 | EU9: 2 | EV9: 3 | EW9: 125.85755 | EZ9: 3 | FA9: 5 | FB9: 157.75876 | FE9: 2 | FF9: 4 | FG9: 125.24384 | FJ9: 2 | FK9: 5 | FL9: 140.03749 | FO9: 2 | FP9: 3 | FQ9: 110.01715 | FT9: 2 | FU9: 5 | FV9: 152.44014 | FY9: 2 | FZ9: 5 | GA9: 95.622905 | GD9: 3 | GE9: 5 | GF9: 144.9144 | GI9: 2 | GJ9: 3 | GK9: 126.80061 | GN9: 2 | GO9: 3 | GP9: 99.376385 | GS9: 2 | GT9: 5 | GU9: 130.20835 | GX9: 2 | GY9: 4 | GZ9: 139.78651 | HC9: 2 | HD9: 5 | HE9: 171.85773 | HH9: 2 | HI9: 5 | HJ9: 165.86484 | HM9: 2 | HN9: 5 | HO9: 112.11985 | HR9: 3 | HS9: 4 | HT9: 131.75937 | HW9: 1 | HX9: 4 | HY9: 143.4896 | IB9: 3 | IC9: 3 | ID9: 103.50059 | IG9: 2 | IH9: 4 | II9: 114.68066 | IL9: 3 | IM9: 6 | IN9: 144.25202 | IQ9: 2 | IR9: 6 | IS9: 128.79624 | IV9: 3 | IW9: 4 | IX9: 155.97292 | JA9: 2 | JB9: 4 | JC9: 105.13048 | JF9: 3 | JG9: 3 | JH9: 117.13713 | JK9: 2 | JL9: 5 | JM9: 116.68919 | JP9: 2 | JQ9: 5 | JR9: 115.44246 | JU9: 2 | JV9: 3 | JW9: 124.10657 | JZ9: 2 | KA9: 4 | KB9: 132.44656 | KE9: 2 | KF9: 5 | KG9: 123.16746 | KJ9: 2 | KK9: 2 | KL9: 112.69577 | KO9: 3 | KP9: 5 | KQ9: 131.66618 | KT9: 2 | KU9: 5 | KV9: 157.38368 | KY9: 2 | KZ9: 5 | LA9: 129.02198 | LD9: 2 | LE9: 5 | LF9: 115.60868 | LI9: 3 | LJ9: 3 | LK9: 119.29958 | LN9: 2 | LO9: 5 | LP9: 134.86583 | LS9: 3 | LT9: 5 | LU9: 120.47666 | LX9: 2 | LY9: 4 | LZ9: 112.01035 | MC9: 2 | MD9: 3 | ME9: 133.15507 | MH9: 2 | MI9: 5 | MJ9: 107.15084 | MM9: 2 | MN9: 3 | MO9: 118.13434 | MR9: 2 | MS9: 4 | MT9: 135.8748 | MW9: 2 | MX9: 4 | MY9: 130.19003 | NB9: 2 | NC9: 6 | ND9: 132.7448 | NG9: 2 | NH9: 2 | NI9: 99.408219 | NL9: 3 | NM9: 5 | NN9: 132.43491 | NQ9: 3 | NR9: 5 | NS9: 110.22476 | NV9: 2 | NW9: 4 | NX9: 114.43544 | OA9: 3 | OB9: 1 | OC9: 105.65921 | OF9: 2 | OG9: 5 | OH9: 130.47803 | OK9: 3 | OL9: 5 | OM9: 163.2878 | OP9: 3 | OQ9: 5 | OR9: 136.52247 | OU9: 2 | OV9: 5 | OW9: 114.87672 | OZ9: 2 | PA9: 6 | PB9: 121.13906 | PE9: 2 | PF9: 3 | PG9: 111.38287 | PJ9: 3 | PK9: 4 | PL9: 110.4467 | PO9: 2 | PP9: 3 | PQ9: 86.989163 | PT9: 2 | PU9: 4 | PV9: 128.60984 | PY9: 2 | PZ9: 4 | QA9: 121.30629 | QD9: 1 | QE9: 3 | QF9: 171.5465 | QI9: 2 | QJ9: 5 | QK9: 147.10744 | QN9: 2 | QO9: 4 | QP9: 111.05031 | QS9: 2 | QT9: 4 | QU9: 116.0632 | QX9: 2 | QY9: 5 | QZ9: 121.58412 | RC9: 2 | RD9: 4 | RE9: 111.28778 | RH9: 2 | RI9: 4 | RJ9: 131.29164 | RM9: 2 | RN9: 3 | RO9: 114.20306 | RR9: 3 | RS9: 6 | RT9: 143.09434 | RW9: 2 | RX9: 6 | RY9: 131.23324 | SB9: 4 | SC9: 2 | SD9: 136.98386
A10: 3 | B10: 5 | C10: 144.69492 | D10: =C10/60 -> 2.411582 | F10: 3 | G10: 4 | H10: 128.38357 | K10: 3 | L10: 3 | M10: 115.87589 | P10: 2 | Q10: 5 | R10: 136.44975 | U10: 3 | V10: 4 | W10: 134.67898 | Z10: 1 | AA10: 6 | AB10: 137.28697 | AE10: 2 | AF10: 5 | AG10: 142.17217 | AJ10: 3 | AK10: 4 | AL10: 125.90008 | AO10: 2 | AP10: 3 | AQ10: 113.99055 | AT10: 1 | AU10: 6 | AV10: 116.51136 | AY10: 2 | AZ10: 4 | BA10: 143.76351 | BD10: 1 | BE10: 6 | BF10: 157.44381 | BI10: 4 | BJ10: 4 | BK10: 125.00477 | BN10: 2 | BO10: 5 | BP10: 143.79959 | BS10: 4 | BT10: 4 | BU10: 160.29988 | BX10: 3 | BY10: 3 | BZ10: 120.57893 | CC10: 2 | CD10: 5 | CE10: 121.58882 | CH10: 2 | CI10: 4 | CJ10: 135.53507 | CM10: 3 | CN10: 4 | CO10: 142.27755 | CR10: 3 | CS10: 3 | CT10: 107.69045 | CW10: 3 | CX10: 6 | CY10: 155.91818 | DB10: 2 | DC10: 5 | DD10: 120.10189 | DG10: 2 | DH10: 5 | DI10: 123.19905 | DL10: 2 | DM10: 4 | DN10: 128.6718 | DQ10: 3 | DR10: 5 | DS10: 174.75679 | DV10: 2 | DW10: 5 | DX10: 123.68225 | EA10: 1 | EB10: 4 | EC10: 117.12809 | EF10: 2 | EG10: 2 | EH10: 108.78749 | EK10: 2 | EL10: 4 | EM10: 126.32168 | EP10: 2 | EQ10: 3 | ER10: 119.25079 | EU10: 3 | EV10: 4 | EW10: 136.55464 | EZ10: 3 | FA10: 5 | FB10: 157.75876 | FE10: 3 | FF10: 5 | FG10: 145.55777 | FJ10: 2 | FK10: 5 | FL10: 140.03749 | FO10: 3 | FP10: 4 | FQ10: 131.72218 | FT10: 2 | FU10: 5 | FV10: 152.44014 | FY10: 2 | FZ10: 5 | GA10: 95.622905 | GD10: 3 | GE10: 5 | GF10: 144.9144 | GI10: 3 | GJ10: 4 | GK10: 161.2255 | GN10: 4 | GO10: 4 | GP10: 136.33606 | GS10: 2 | GT10: 5 | GU10: 130.20835 | GX10: 2 | GY10: 4 | GZ10: 139.78651 | HC10: 2 | HD10: 5 | HE10: 171.85773 | HH10: 2 | HI10: 5 | HJ10: 165.86484 | HM10: 3 | HN10: 5 | HO10: 147.02083 | HR10: 3 | HS10: 4 | HT10: 131.75937 | HW10: 1 | HX10: 4 | HY10: 143.4896 | IB10: 3 | IC10: 3 | ID10: 103.50059 | IG10: 2 | IH10: 4 | II10: 114.68066 | IL10: 3 | IM10: 6 | IN10: 144.25202 | IQ10: 2 | IR10: 6 | IS10: 128.79624 | IV10: 2 | IW10: 4 | IX10: 172.98879 | JA10: 4 | JB10: 1 | JC10: 139.02244 | JF10: 2 | JG10: 4 | JH10: 128.71128 | JK10: 2 | JL10: 5 | JM10: 116.68919 | JP10: 2 | JQ10: 5 | JR10: 115.44246 | JU10: 2 | JV10: 3 | JW10: 124.10657 | JZ10: 2 | KA10: 4 | KB10: 132.44656 | KE10: 2 | KF10: 5 | KG10: 123.16746 | KJ10: 3 | KK10: 5 | KL10: 128.8132 | KO10: 3 | KP10: 5 | KQ10: 131.66618 | KT10: 2 | KU10: 5 | KV10: 157.38368 | KY10: 2 | KZ10: 5 | LA10: 129.02198 | LD10: 2 | LE10: 5 | LF10: 115.60868 | LI10: 3 | LJ10: 3 | LK10: 119.29958 | LN10: 2 | LO10: 5 | LP10: 134.86583 | LS10: 3 | LT10: 5 | LU10: 120.47666 | LX10: 2 | LY10: 4 | LZ10: 112.01035 | MC10: 2 | MD10: 3 | ME10: 133.15507 | MH10: 2 | MI10: 5 | MJ10: 107.15084 | MM10: 2 | MN10: 3 | MO10: 118.13434 | MR10: 2 | MS10: 4 | MT10: 135.8748 | MW10: 2 | MX10: 4 | MY10: 130.19003 | NB10: 2 | NC10: 6 | ND10: 132.7448 | NG10: 3 | NH10: 4 | NI10: 141.00713 | NL10: 3 | NM10: 5 | NN10: 132.43491 | NQ10: 3 | NR10: 5 | NS10: 110.22476 | NV10: 2 | NW10: 4 | NX10: 114.43544 | OA10: 4 | OB10: 4 | OC10: 130.07021 | OF10: 2 | OG10: 5 | OH10: 130.47803 | OK10: 3 | OL10: 5 | OM10: 163.2878 | OP10: 3 | OQ10: 5 | OR10: 136.52247 | OU10: 2 | OV10: 5 | OW10: 114.87672 | OZ10: 2 | PA10: 6 | PB10: 121.13906 | PE10: 3 | PF10: 4 | PG10: 150.96612 | PJ10: 3 | PK10: 4 | PL10: 110.4467 | PO10: 3 | PP10: 4 | PQ10: 161.03957 | PT10: 2 | PU10: 4 | PV10: 128.60984 | PY10: 2 | PZ10: 4 | QA10: 121.30629 | QD10: 1 | QE10: 3 | QF10: 171.5465 | QI10: 2 | QJ10: 5 | QK10: 147.10744 | QN10: 2 | QO10: 4 | QP10: 111.05031 | QS10: 2 | QT10: 4 | QU10: 116.0632 | QX10: 2 | QY10: 5 | QZ10: 121.58412 | RC10: 3 | RD10: 3 | RE10: 140.6641 | RH10: 2 | RI10: 4 | RJ10: 131.29164 | RM10: 3 | RN10: 4 | RO10: 136.74662 | RR10: 3 | RS10: 6 | RT10: 143.09434 | RW10: 2 | RX10: 6 | RY10: 131.23324 | SB10: 4 | SC10: 2 | SD10: 136.98386
A11: 3 | B11: 5 | C11: 144.69492 | D11: =C11/60 -> 2.411582 | F11: 3 | G11: 4 | H11: 128.38357 | K11: 3 | L11: 3 | M11: 115.87589 | P11: 2 | Q11: 5 | R11: 136.44975 | U11: 3 | V11: 4 | W11: 134.67898 | Z11: 1 | AA11: 6 | AB11: 137.28697 | AE11: 2 | AF11: 5 | AG11: 142.17217 | AJ11: 3 | AK11: 4 | AL11: 125.90008 | AO11: 3 | AP11: 4 | AQ11: 142.24797 | AT11: 3 | AU11: 5 | AV11: 164.49457 | AY11: 2 | AZ11: 4 | BA11: 143.76351 | BD11: 1 | BE11: 6 | BF11: 157.44381 | BI11: 4 | BJ11: 4 | BK11: 125.00477 | BN11: 2 | BO11: 5 | BP11: 143.79959 | BS11: 4 | BT11: 4 | BU11: 160.29988 | BX11: 3 | BY11: 3 | BZ11: 120.57893 | CC11: 3 | CD11: 5 | CE11: 166.42793 | CH11: 3 | CI11: 4 | CJ11: 152.93695 | CM11: 3 | CN11: 4 | CO11: 142.27755 | CR11: 3 | CS11: 3 | CT11: 107.69045 | CW11: 3 | CX11: 6 | CY11: 155.91818 | DB11: 2 | DC11: 5 | DD11: 120.10189 | DG11: 2 | DH11: 5 | DI11: 123.19905 | DL11: 2 | DM11: 4 | DN11: 128.6718 | DQ11: 3 | DR11: 5 | DS11: 174.75679 | DV11: 2 | DW11: 5 | DX11: 123.68225 | EA11: 5 | EB11: 2 | EC11: 236.76216 | EF11: 3 | EG11: 5 | EH11: 128.64208 | EK11: 3 | EL11: 5 | EM11: 138.2461 | EP11: 4 | EQ11: 4 | ER11: 127.86076 | EU11: 3 | EV11: 4 | EW11: 136.55464 | EZ11: 3 | FA11: 5 | FB11: 157.75876 | FE11: 3 | FF11: 5 | FG11: 145.55777 | FJ11: 3 | FK11: 4 | FL11: 167.69643 | FO11: 3 | FP11: 4 | FQ11: 131.72218 | FT11: 2 | FU11: 5 | FV11: 152.44014 | FY11: 3 | FZ11: 3 | GA11: 128.26675 | GD11: 3 | GE11: 5 | GF11: 144.9144 | GI11: 3 | GJ11: 4 | GK11: 161.2255 | GN11: 4 | GO11: 4 | GP11: 136.33606 | GS11: 2 | GT11: 5 | GU11: 130.20835 | GX11: 2 | GY11: 4 | GZ11: 139.78651 | HC11: 2 | HD11: 5 | HE11: 171.85773 | HH11: 2 | HI11: 5 | HJ11: 165.86484 | HM11: 3 | HN11: 5 | HO11: 147.02083 | HR11: 3 | HS11: 4 | HT11: 131.75937 | HW11: 1 | HX11: 4 | HY11: 143.4896 | IB11: 4 | IC11: 4 | ID11: 126.07715 | IG11: 3 | IH11: 5 | II11: 146.97866 | IL11: 3 | IM11: 6 | IN11: 144.25202 | IQ11: 2 | IR11: 6 | IS11: 128.79624 | IV11: 2 | IW11: 4 | IX11: 172.98879 | JA11: 3 | JB11: 6 | JC11: 146.83412 | JF11: 2 | JG11: 4 | JH11: 128.71128 | JK11: 2 | JL11: 5 | JM11: 116.68919 | JP11: 2 | JQ11: 5 | JR11: 115.44246 | JU11: 3 | JV11: 4 | JW11: 151.88892 | JZ11: 2 | KA11: 4 | KB11: 132.44656 | KE11: 2 | KF11: 5 | KG11: 123.16746 | KJ11: 3 | KK11: 5 | KL11: 128.8132 | KO11: 2 | KP11: 5 | KQ11: 151.1988 | KT11: 2 | KU11: 5 | KV11: 157.38368 | KY11: 2 | KZ11: 5 | LA11: 129.02198 | LD11: 4 | LE11: 2 | LF11: 143.27035 | LI11: 3 | LJ11: 3 | LK11: 119.29958 | LN11: 3 | LO11: 5 | LP11: 151.0847 | LS11: 3 | LT11: 5 | LU11: 120.47666 | LX11: 3 | LY11: 4 | LZ11: 135.93891 | MC11: 2 | MD11: 3 | ME11: 133.15507 | MH11: 2 | MI11: 5 | MJ11: 107.15084 | MM11: 2 | MN11: 3 | MO11: 118.13434 | MR11: 2 | MS11: 4 | MT11: 135.8748 | MW11: 2 | MX11: 4 | MY11: 130.19003 | NB11: 2 | NC11: 6 | ND11: 132.7448 | NG11: 3 | NH11: 4 | NI11: 141.00713 | NL11: 2 | NM11: 5 | NN11: 178.65879 | NQ11: 3 | NR11: 5 | NS11: 110.22476 | NV11: 3 | NW11: 5 | NX11: 135.19785 | OA11: 4 | OB11: 4 | OC11: 130.07021 | OF11: 2 | OG11: 5 | OH11: 130.47803 | OK11: 3 | OL11: 5 | OM11: 163.2878 | OP11: 3 | OQ11: 5 | OR11: 136.52247 | OU11: 3 | OV11: 5 | OW11: 182.39087 | OZ11: 2 | PA11: 6 | PB11: 121.13906 | PE11: 3 | PF11: 4 | PG11: 150.96612 | PJ11: 3 | PK11: 4 | PL11: 110.4467 | PO11: 3 | PP11: 4 | PQ11: 161.03957 | PT11: 2 | PU11: 4 | PV11: 128.60984 | PY11: 2 | PZ11: 4 | QA11: 121.30629 | QD11: 1 | QE11: 3 | QF11: 171.5465 | QI11: 2 | QJ11: 5 | QK11: 147.10744 | QN11: 3 | QO11: 4 | QP11: 127.67935 | QS11: 3 | QT11: 5 | QU11: 149.50606 | QX11: 2 | QY11: 5 | QZ11: 121.58412 | RC11: 3 | RD11: 3 | RE11: 140.6641 | RH11: 2 | RI11: 4 | RJ11: 131.29164 | RM11: 3 | RN11: 4 | RO11: 136.74662 | RR11: 3 | RS11: 6 | RT11: 143.09434 | RW11: 2 | RX11: 6 | RY11: 131.23324 | SB11: 5 | SC11: 6 | SD11: 191.18455
A12: 3 | B12: 5 | C12: 144.69492 | D12: =C12/60 -> 2.411582 | F12: 3 | G12: 4 | H12: 128.38357 | K12: 3 | L12: 3 | M12: 115.87589 | P12: 2 | Q12: 5 | R12: 136.44975 | U12: 2 | V12: 4 | W12: 165.85546 | Z12: 1 | AA12: 6 | AB12: 137.28697 | AE12: 2 | AF12: 5 | AG12: 142.17217 | AJ12: 3 | AK12: 4 | AL12: 125.90008 | AO12: 3 | AP12: 4 | AQ12: 142.24797 | AT12: 3 | AU12: 5 | AV12: 164.49457 | AY12: 3 | AZ12: 5 | BA12: 158.80171 | BD12: 1 | BE12: 6 | BF12: 157.44381 | BI12: 4 | BJ12: 4 | BK12: 125.00477 | BN12: 4 | BO12: 3 | BP12: 189.61666 | BS12: 4 | BT12: 4 | BU12: 160.29988 | BX12: 4 | BY12: 5 | BZ12: 158.04289 | CC12: 3 | CD12: 5 | CE12: 166.42793 | CH12: 3 | CI12: 4 | CJ12: 152.93695 | CM12: 3 | CN12: 4 | CO12: 142.27755 | CR12: 3 | CS12: 3 | CT12: 107.69045 | CW12: 3 | CX12: 6 | CY12: 155.91818 | DB12: 2 | DC12: 5 | DD12: 120.10189 | DG12: 2 | DH12: 5 | DI12: 123.19905 | DL12: 2 | DM12: 4 | DN12: 128.6718 | DQ12: 3 | DR12: 5 | DS12: 174.75679 | DV12: 2 | DW12: 5 | DX12: 123.68225 | EA12: 5 | EB12: 2 | EC12: 236.76216 | EF12: 3 | EG12: 5 | EH12: 128.64208 | EK12: 3 | EL12: 5 | EM12: 138.2461 | EP12: 4 | EQ12: 4 | ER12: 127.86076 | EU12: 3 | EV12: 4 | EW12: 136.55464 | EZ12: 3 | FA12: 5 | FB12: 157.75876 | FE12: 3 | FF12: 5 | FG12: 145.55777 | FJ12: 3 | FK12: 4 | FL12: 167.69643 | FO12: 3 | FP12: 4 | FQ12: 131.72218 | FT12: 2 | FU12: 5 | FV12: 152.44014 | FY12: 3 | FZ12: 3 | GA12: 128.26675 | GD12: 3 | GE12: 5 | GF12: 144.9144 | GI12: 3 | GJ12: 4 | GK12: 161.2255 | GN12: 4 | GO12: 4 | GP12: 136.33606 | GS12: 2 | GT12: 5 | GU12: 130.20835 | GX12: 3 | GY12: 6 | GZ12: 169.1819 | HC12: 2 | HD12: 5 | HE12: 171.85773 | HH12: 2 | HI12: 5 | HJ12: 165.86484 | HM12: 3 | HN12: 5 | HO12: 147.02083 | HR12: 3 | HS12: 4 | HT12: 131.75937 | HW12: 3 | HX12: 3 | HY12: 159.27982 | IB12: 4 | IC12: 4 | ID12: 126.07715 | IG12: 3 | IH12: 5 | II12: 146.97866 | IL12: 3 | IM12: 6 | IN12: 144.25202 | IQ12: 2 | IR12: 6 | IS12: 128.79624 | IV12: 2 | IW12: 4 | IX12: 172.98879 | JA12: 3 | JB12: 6 | JC12: 146.83412 | JF12: 2 | JG12: 4 | JH12: 128.71128 | JK12: 2 | JL12: 5 | JM12: 116.68919 | JP12: 2 | JQ12: 5 | JR12: 115.44246 | JU12: 3 | JV12: 4 | JW12: 151.88892 | JZ12: 2 | KA12: 4 | KB12: 132.44656 | KE12: 2 | KF12: 5 | KG12: 123.16746 | KJ12: 3 | KK12: 5 | KL12: 128.8132 | KO12: 2 | KP12: 5 | KQ12: 151.1988 | KT12: 3 | KU12: 3 | KV12: 181.70843 | KY12: 3 | KZ12: 4 | LA12: 177.47575 | LD12: 4 | LE12: 2 | LF12: 143.27035 | LI12: 4 | LJ12: 2 | LK12: 127.57856 | LN12: 3 | LO12: 5 | LP12: 151.0847 | LS12: 3 | LT12: 5 | LU12: 120.47666 | LX12: 3 | LY12: 4 | LZ12: 135.93891 | MC12: 4 | MD12: 5 | ME12: 162.3826 | MH12: 3 | MI12: 6 | MJ12: 154.93243 | MM12: 4 | MN12: 4 | MO12: 157.99197 | MR12: 2 | MS12: 4 | MT12: 135.8748 | MW12: 2 | MX12: 4 | MY12: 130.19003 | NB12: 2 | NC12: 6 | ND12: 132.7448 | NG12: 3 | NH12: 4 | NI12: 141.00713 | NL12: 2 | NM12: 5 | NN12: 178.65879 | NQ12: 4 | NR12: 4 | NS12: 140.61477 | NV12: 3 | NW12: 5 | NX12: 135.19785 | OA12: 4 | OB12: 4 | OC12: 130.07021 | OF12: 2 | OG12: 5 | OH12: 130.47803 | OK12: 3 | OL12: 5 | OM12: 163.2878 | OP12: 3 | OQ12: 5 | OR12: 136.52247 | OU12: 3 | OV12: 5 | OW12: 182.39087 | OZ12: 3 | PA12: 4 | PB12: 147.11176 | PE12: 3 | PF12: 4 | PG12: 150.96612 | PJ12: 2 | PK12: 3 | PL12: 133.81391 | PO12: 3 | PP12: 4 | PQ12: 161.03957 | PT12: 2 | PU12: 4 | PV12: 128.60984 | PY12: 3 | PZ12: 4 | QA12: 153.65809 | QD12: 4 | QE12: 5 | QF12: 183.47234 | QI12: 2 | QJ12: 5 | QK12: 147.10744 | QN12: 3 | QO12: 4 | QP12: 127.67935 | QS12: 3 | QT12: 5 | QU12: 149.50606 | QX12: 2 | QY12: 5 | QZ12: 121.58412 | RC12: 3 | RD12: 3 | RE12: 140.6641 | RH12: 2 | RI12: 4 | RJ12: 131.29164 | RM12: 3 | RN12: 4 | RO12: 136.74662 | RR12: 3 | RS12: 6 | RT12: 143.09434 | RW12: 2 | RX12: 6 | RY12: 131.23324 | SB12: 5 | SC12: 6 | SD12: 191.18455
A13: 3 | B13: 5 | C13: 144.69492 | D13: =C13/60 -> 2.411582 | F13: 4 | G13: 3 | H13: 177.86169 | K13: 4 | L13: 3 | M13: 125.65741 | P13: 3 | Q13: 6 | R13: 147.66769 | U13: 2 | V13: 4 | W13: 165.85546 | Z13: 4 | AA13: 4 | AB13: 154.23798 | AE13: 2 | AF13: 5 | AG13: 142.17217 | AJ13: 3 | AK13: 4 | AL13: 125.90008 | AO13: 3 | AP13: 4 | AQ13: 142.24797 | AT13: 3 | AU13: 5 | AV13: 164.49457 | AY13: 3 | AZ13: 5 | BA13: 158.80171 | BD13: 3 | BE13: 5 | BF13: 140.569 | BI13: 3 | BJ13: 2 | BK13: 167.45305 | BN13: 4 | BO13: 3 | BP13: 189.61666 | BS13: 4 | BT13: 4 | BU13: 160.29988 | BX13: 4 | BY13: 5 | BZ13: 158.04289 | CC13: 3 | CD13: 5 | CE13: 166.42793 | CH13: 3 | CI13: 4 | CJ13: 152.93695 | CM13: 3 | CN13: 4 | CO13: 142.27755 | CR13: 4 | CS13: 5 | CT13: 154.73713 | CW13: 3 | CX13: 6 | CY13: 155.91818 | DB13: 3 | DC13: 4 | DD13: 149.87589 | DG13: 3 | DH13: 3 | DI13: 149.66102 | DL13: 4 | DM13: 4 | DN13: 150.9273 | DQ13: 3 | DR13: 5 | DS13: 174.75679 | DV13: 3 | DW13: 4 | DX13: 153.42978 | EA13: 6 | EB13: 6 | EC13: 245.66457 | EF13: 3 | EG13: 5 | EH13: 128.64208 | EK13: 3 | EL13: 5 | EM13: 138.2461 | EP13: 4 | EQ13: 4 | ER13: 127.86076 | EU13: 3 | EV13: 4 | EW13: 136.55464 | EZ13: 3 | FA13: 5 | FB13: 157.75876 | FE13: 3 | FF13: 5 | FG13: 145.55777 | FJ13: 3 | FK13: 4 | FL13: 167.69643 | FO13: 3 | FP13: 4 | FQ13: 131.72218 | FT13: 3 | FU13: 5 | FV13: 153.86906 | FY13: 3 | FZ13: 3 | GA13: 128.26675 | GD13: 3 | GE13: 5 | GF13: 144.9144 | GI13: 3 | GJ13: 4 | GK13: 161.2255 | GN13: 4 | GO13: 4 | GP13: 136.33606 | GS13: 2 | GT13: 5 | GU13: 130.20835 | GX13: 3 | GY13: 6 | GZ13: 169.1819 | HC13: 2 | HD13: 5 | HE13: 171.85773 | HH13: 2 | HI13: 5 | HJ13: 165.86484 | HM13: 3 | HN13: 5 | HO13: 147.02083 | HR13: 4 | HS13: 3 | HT13: 136.79725 | HW13: 3 | HX13: 3 | HY13: 159.27982 | IB13: 4 | IC13: 4 | ID13: 126.07715 | IG13: 3 | IH13: 5 | II13: 146.97866 | IL13: 4 | IM13: 3 | IN13: 144.47229 | IQ13: 4 | IR13: 4 | IS13: 163.83889 | IV13: 2 | IW13: 4 | IX13: 172.98879 | JA13: 3 | JB13: 6 | JC13: 146.83412 | JF13: 2 | JG13: 4 | JH13: 128.71128 | JK13: 2 | JL13: 5 | JM13: 116.68919 | JP13: 3 | JQ13: 4 | JR13: 146.21301 | JU13: 3 | JV13: 4 | JW13: 151.88892 | JZ13: 4 | KA13: 4 | KB13: 150.19182 | KE13: 3 | KF13: 6 | KG13: 162.7812 | KJ13: 3 | KK13: 5 | KL13: 128.8132 | KO13: 2 | KP13: 5 | KQ13: 151.1988 | KT13: 3 | KU13: 3 | KV13: 181.70843 | KY13: 3 | KZ13: 4 | LA13: 177.47575 | LD13: 5 | LE13: 3 | LF13: 165.87073 | LI13: 4 | LJ13: 2 | LK13: 127.57856 | LN13: 3 | LO13: 5 | LP13: 151.0847 | LS13: 4 | LT13: 5 | LU13: 154.65979 | LX13: 3 | LY13: 4 | LZ13: 135.93891 | MC13: 4 | MD13: 5 | ME13: 162.3826 | MH13: 3 | MI13: 6 | MJ13: 154.93243 | MM13: 4 | MN13: 4 | MO13: 157.99197 | MR13: 5 | MS13: 4 | MT13: 198.19173 | MW13: 4 | MX13: 5 | MY13: 175.36603 | NB13: 2 | NC13: 6 | ND13: 132.7448 | NG13: 3 | NH13: 4 | NI13: 141.00713 | NL13: 2 | NM13: 5 | NN13: 178.65879 | NQ13: 4 | NR13: 4 | NS13: 140.61477 | NV13: 3 | NW13: 5 | NX13: 135.19785 | OA13: 4 | OB13: 4 | OC13: 130.07021 | OF13: 3 | OG13: 3 | OH13: 139.28524 | OK13: 4 | OL13: 5 | OM13: 200.60655 | OP13: 3 | OQ13: 5 | OR13: 136.52247 | OU13: 3 | OV13: 5 | OW13: 182.39087 | OZ13: 3 | PA13: 4 | PB13: 147.11176 | PE13: 3 | PF13: 4 | PG13: 150.96612 | PJ13: 2 | PK13: 3 | PL13: 133.81391 | PO13: 3 | PP13: 4 | PQ13: 161.03957 | PT13: 5 | PU13: 3 | PV13: 164.17659 | PY13: 3 | PZ13: 4 | QA13: 153.65809 | QD13: 4 | QE13: 5 | QF13: 183.47234 | QI13: 3 | QJ13: 5 | QK13: 136.98925 | QN13: 3 | QO13: 4 | QP13: 127.67935 | QS13: 3 | QT13: 5 | QU13: 149.50606 | QX13: 4 | QY13: 3 | QZ13: 149.05451 | RC13: 4 | RD13: 4 | RE13: 129.87864 | RH13: 4 | RI13: 5 | RJ13: 158.94245 | RM13: 3 | RN13: 4 | RO13: 136.74662 | RR13: 3 | RS13: 6 | RT13: 143.09434 | RW13: 3 | RX13: 5 | RY13: 160.81762 | SB13: 5 | SC13: 6 | SD13: 191.18455
A14: 5 | B14: 4 | C14: 181.58579 | D14: =C14/60 -> 3.0264299 | F14: 4 | G14: 3 | H14: 177.86169 | K14: 4 | L14: 3 | M14: 125.65741 | P14: 3 | Q14: 6 | R14: 147.66769 | U14: 2 | V14: 4 | W14: 165.85546 | Z14: 4 | AA14: 4 | AB14: 154.23798 | AE14: 4 | AF14: 4 | AG14: 165.92612 | AJ14: 4 | AK14: 4 | AL14: 150.49274 | AO14: 3 | AP14: 4 | AQ14: 142.24797 | AT14: 3 | AU14: 5 | AV14: 164.49457 | AY14: 3 | AZ14: 5 | BA14: 158.80171 | BD14: 3 | BE14: 5 | BF14: 140.569 | BI14: 3 | BJ14: 2 | BK14: 167.45305 | BN14: 4 | BO14: 3 | BP14: 189.61666 | BS14: 3 | BT14: 5 | BU14: 204.03514 | BX14: 4 | BY14: 5 | BZ14: 158.04289 | CC14: 3 | CD14: 5 | CE14: 166.42793 | CH14: 3 | CI14: 4 | CJ14: 152.93695 | CM14: 4 | CN14: 4 | CO14: 131.08398 | CR14: 4 | CS14: 5 | CT14: 154.73713 | CW14: 3 | CX14: 6 | CY14: 155.91818 | DB14: 3 | DC14: 4 | DD14: 149.87589 | DG14: 3 | DH14: 3 | DI14: 149.66102 | DL14: 4 | DM14: 4 | DN14: 150.9273 | DQ14: 2 | DR14: 4 | DS14: 198.78321 | DV14: 3 | DW14: 4 | DX14: 153.42978 | EA14: 6 | EB14: 6 | EC14: 245.66457 | EF14: 3 | EG14: 5 | EH14: 128.64208 | EK14: 3 | EL14: 5 | EM14: 138.2461 | EP14: 4 | EQ14: 4 | ER14: 127.86076 | EU14: 4 | EV14: 5 | EW14: 153.91644 | EZ14: 4 | FA14: 5 | FB14: 177.93193 | FE14: 3 | FF14: 5 | FG14: 145.55777 | FJ14: 3 | FK14: 4 | FL14: 167.69643 | FO14: 4 | FP14: 4 | FQ14: 156.67044 | FT14: 3 | FU14: 5 | FV14: 153.86906 | FY14: 4 | FZ14: 3 | GA14: 119.62746 | GD14: 6 | GE14: 3 | GF14: 165.17014 | GI14: 4 | GJ14: 4 | GK14: 185.36347 | GN14: 3 | GO14: 2 | GP14: 138.37419 | GS14: 3 | GT14: 2 | GU14: 147.99823 | GX14: 3 | GY14: 6 | GZ14: 169.1819 | HC14: 3 | HD14: 5 | HE14: 210.75585 | HH14: 3 | HI14: 4 | HJ14: 156.52741 | HM14: 3 | HN14: 5 | HO14: 147.02083 | HR14: 4 | HS14: 3 | HT14: 136.79725 | HW14: 3 | HX14: 3 | HY14: 159.27982 | IB14: 4 | IC14: 4 | ID14: 126.07715 | IG14: 3 | IH14: 5 | II14: 146.97866 | IL14: 4 | IM14: 3 | IN14: 144.47229 | IQ14: 4 | IR14: 4 | IS14: 163.83889 | IV14: 4 | IW14: 3 | IX14: 174.29308 | JA14: 3 | JB14: 6 | JC14: 146.83412 | JF14: 5 | JG14: 4 | JH14: 165.52247 | JK14: 3 | JL14: 3 | JM14: 167.58199 | JP14: 3 | JQ14: 4 | JR14: 146.21301 | JU14: 3 | JV14: 4 | JW14: 151.88892 | JZ14: 4 | KA14: 4 | KB14: 150.19182 | KE14: 3 | KF14: 6 | KG14: 162.7812 | KJ14: 3 | KK14: 5 | KL14: 128.8132 | KO14: 2 | KP14: 5 | KQ14: 151.1988 | KT14: 3 | KU14: 3 | KV14: 181.70843 | KY14: 3 | KZ14: 4 | LA14: 177.47575 | LD14: 5 | LE14: 3 | LF14: 165.87073 | LI14: 5 | LJ14: 5 | LK14: 153.40807 | LN14: 3 | LO14: 5 | LP14: 151.0847 | LS14: 4 | LT14: 5 | LU14: 154.65979 | LX14: 3 | LY14: 4 | LZ14: 135.93891 | MC14: 4 | MD14: 5 | ME14: 162.3826 | MH14: 3 | MI14: 6 | MJ14: 154.93243 | MM14: 4 | MN14: 4 | MO14: 157.99197 | MR14: 5 | MS14: 4 | MT14: 198.19173 | MW14: 4 | MX14: 5 | MY14: 175.36603 | NB14: 3 | NC14: 5 | ND14: 185.11715 | NG14: 4 | NH14: 4 | NI14: 141.85653 | NL14: 2 | NM14: 5 | NN14: 178.65879 | NQ14: 4 | NR14: 4 | NS14: 140.61477 | NV14: 3 | NW14: 5 | NX14: 135.19785 | OA14: 5 | OB14: 4 | OC14: 142.22837 | OF14: 3 | OG14: 3 | OH14: 139.28524 | OK14: 4 | OL14: 5 | OM14: 200.60655 | OP14: 4 | OQ14: 4 | OR14: 143.25648 | OU14: 3 | OV14: 5 | OW14: 182.39087 | OZ14: 3 | PA14: 4 | PB14: 147.11176 | PE14: 4 | PF14: 5 | PG14: 186.57327 | PJ14: 2 | PK14: 3 | PL14: 133.81391 | PO14: 4 | PP14: 3 | PQ14: 178.81811 | PT14: 5 | PU14: 3 | PV14: 164.17659 | PY14: 3 | PZ14: 4 | QA14: 153.65809 | QD14: 4 | QE14: 5 | QF14: 183.47234 | QI14: 3 | QJ14: 5 | QK14: 136.98925 | QN14: 3 | QO14: 4 | QP14: 127.67935 | QS14: 3 | QT14: 5 | QU14: 149.50606 | QX14: 4 | QY14: 3 | QZ14: 149.05451 | RC14: 4 | RD14: 4 | RE14: 129.87864 | RH14: 4 | RI14: 5 | RJ14: 158.94245 | RM14: 4 | RN14: 4 | RO14: 162.02074 | RR14: 3 | RS14: 6 | RT14: 143.09434 | RW14: 3 | RX14: 5 | RY14: 160.81762 | SB14: 5 | SC14: 6 | SD14: 191.18455
